Workbook

Sheet COVER 
C6: BUKU
C7: ADMINISTRASI PENDIDIK
C8: PENYUSUNAN PROGRAM
D26: Program Keahlian | G26: : | H26: Teknik Elektronika
D27: Konsentrasi Keahlian | G27: : | H27: Elektronika Industri
D28: Mata Pelajaran | G28: : | H28: Pemrograman Sistem Embeded
D29: Fase | G29: : | H29: F
D30: Kelas | G30: : | H30: XI
D31: Semester | G31: : | H31: Gasal
D32: Tahun Pelajaran | G32: : | H32: 2024/2025
D34: Nama Pendidik | G34: : | H34: Jumari, S.Pd.T., M.Eng
D35: N I P | G35: : | H35: 1.9831115e+17
C38: SMK NEGERI 3 YOGYAKARTA
C39: JL. R. W. MONGINSIDI NO. 2 YOGYAKARTA 55233
C40: Telp./Fax : (0274) 513503, e-mail : humas@smkn3jogja.sch.id

Sheet Visi,Misi,Tuj&KebjkMutu
A1: VISI, MISI, TUJUAN DAN KEBIJAKAN MUTU
A2: SMK NEGERI 3 YOGYAKARTA
A3: VISI :
B4: Menjadi Lembaga Pendidikan dan Pelatihan yang mampu menyiapkan tamatan berkarakter, kompeten, berbudaya dan berwawasan lingkungan.
A5: MISI :
A6: 1 | B6: Melaksanakan Pendidikan dan Pelatihan untuk menghasilkan tamatan yang beriman, bertaqwa, kompeten, dan mandiri.
A7: 2 | B7: Melaksanakan Pendidikan dan Pelatihan untuk menghasilkan tamatan unggul dalam iptek dan mampu berkompetisi pada era globalisasi.
A8: 3 | B8: Melaksanakan Pendidikan dan Pelatihan yang berkualitas dengan standar Nasional.
A9: 4 | B9: Melaksanakan Pendidikan dan Pelatihan dengan menumbuhkan dan melestarikan budaya lokal.
A10: 5 | B10: Melaksanakan Pendidikan dan Pelatihan dengan membiasakan Warga Sekolah agar selalu peduli terhadap lingkungan.
A12: TUJUAN :
A14: 1 | B14: Menghasilkan tamatan yang beriman, bertaqwa, kompeten dan mandiri.
A15: 2 | B15: Menghasilkan tamatan yang unggul dalam iptek, mampu berkompetisi pada era globalisasi tanpa meninggalkan kearifan lokal.
A16: 3 | B16: Menjadi Lembaga Pendidikan dan Pelatihan yang berkualitas dengan standar Nasional.
A17: 4 | B17: Menampilkan sarana dan prasarana sekolah dengan wujud budaya jogja.
A18: 5 | B18: Menampilkan sikap sopan, santun dan budi pekerti sebagai cermin akhlak mulia tanpa meninggalkan budaya jogja.
A19: 6 | B19: Mengembangkan lingkungan sekolah menjadi sekolah adiwiyata dengan melibatkan warga sekolah, stake holder dan instansi terkait.
A21: KEBIJAKAN MUTU :
A23: H | B23: umanis | D23: KON | E23: struktif
A24: A | B24: gamis | D24: S | E24: istematis
A25: N | B25: ormatif | D25: I | E25: nteraktif
A26: D | B26: inamis | D26: S | E26: olutif
A27: A | B27: daptif | D27: T | E27: aktis
A28: L | B28: oyal | D28: E | E28: fektif-Efisien
D29: N | E29: yaman

Sheet Daftar Isi 
B2: DAFTAR ISI
B4: 1 | C4: Kalender pendidikan
B5: 2 | C5: Jadwal pelajaran
B6: 3 | C6: Perhitungan minggu efektif
B7: 4 | C7: Program tahunan
B8: 5 | C8: Program semester
B9: 6 | C9: Analisis CP
B10: 7 | C10: Analisa Materi
B11: 8 | C11: ATP
B12: 9 | C12: TP
B13: 10 | C13: KKTP
B14: 11 | C14: MA-LKPD
B15: 12 | C15: Daftar Hadir
... B29: 26 | C29: Telaah Soal Essay

Sheet Kalender Akademik (1)
M1: F/751/WKS1/-/01
M2: 45483
C4: SMK NEGERI 3 YOGYAKARTA
C5: KALENDER PENDIDIKAN TP 2024/2025
C7: SEMESTER I TAHUN PELAJARAN 2024/2025
C8: JULI 2024
C9: AHAD | E9: 7 | F9: 14 | G9: 21 | H9: 28 | K9: CATATAN
C10: SENIN | D10: 1 | E10: 8 | F10: 15 | G10: 22 | H10: 29 | K10: 1 - 12 Juli 2024 : Libur Akhir Tahun Pelajaran 2023/2024
C11: SELASA | D11: 2 | E11: 9 | F11: 16 | G11: 23 | H11: 30 | K11: 7 Juli 2024: Tahun Baru Islam 1446 H
C12: RABU | D12: 3 | E12: 10 | F12: 17 | G12: 24 | H12: 31 | K12: 15 - 19 Juli 2024 : PLS Tahun Pelajaran 2024/2025
C13: KAMIS | D13: 4 | E13: 11 | F13: 18 | G13: 25
C14: JUMÁT | D14: 5 | E14: 12 | F14: 19 | G14: 26
C15: SABTU | D15: 6 | E15: 13 | F15: 20 | G15: 27
C17: AGUSTUS 2024
C18: AHAD | E18: 4 | F18: 11 | G18: 18 | H18: 25 | K18: CATATAN
C19: SENIN | E19: 5 | F19: 12 | G19: 19 | H19: 26 | K19: 17 Agustus 2024 : Hari Kemerdekaan RI ke-79
C20: SELASA | E20: 6 | F20: 13 | G20: 20 | H20: 27 | K20: 19 - 22 Agustus 2024 : ANBK Jenjang SMK Sederajat
C21: RABU | E21: 7 | F21: 14 | G21: 21 | H21: 28
C22: KAMIS | D22: 1 | E22: 8 | F22: 15 | G22: 22 | H22: 29
C23: JUMÁT | D23: 2 | E23: 9 | F23: 16 | G23: 23 | H23: 30
C24: SABTU | D24: 3 | E24: 10 | F24: 17 | G24: 24 | H24: 31
C26: SEPTEMBER 2024
C27: AHAD | D27: 1 | E27: 8 | F27: 15 | G27: 22 | H27: 29 | K27: CATATAN
C28: SENIN | D28: 2 | E28: 9 | F28: 16 | G28: 23 | H28: 30 | K28: 16 September 2024 : Maulid Nabi Muhammad SAW
C29: SELASA | D29: 3 | E29: 10 | F29: 17 | G29: 24
C30: RABU | D30: 4 | E30: 11 | F30: 18 | G30: 25
C31: KAMIS | D31: 5 | E31: 12 | F31: 19 | G31: 26
C32: JUMÁT | D32: 6 | E32: 13 | F32: 20 | G32: 27
C33: SABTU | D33: 7 | E33: 14 | F33: 21 | G33: 28
C35: OKTOBER 2024
C36: AHAD | E36: 6 | F36: 13 | G36: 20 | H36: 27 | K36: CATATAN
C37: SENIN | E37: 7 | F37: 14 | G37: 21 | H37: 28 | K37: 14 Okto 2024 awal mulai PKL
C38: SELASA | D38: 1 | E38: 8 | F38: 15 | G38: 22 | H38: 29 | K38: 7-11 Oktober 2024 AAS tingkat 12
C39: RABU | D39: 2 | E39: 9 | F39: 16 | G39: 23 | H39: 30
C40: KAMIS | D40: 3 | E40: 10 | F40: 17 | G40: 24 | H40: 31
C41: JUMÁT | D41: 4 | E41: 11 | F41: 18 | G41: 25
C42: SABTU | D42: 5 | E42: 12 | F42: 19 | G42: 26
C44: NOPEMBER 2024
C45: AHAD | E45: 3 | F45: 10 | G45: 17 | H45: 24 | K45: CATATAN
C46: SENIN | E46: 4 | F46: 11 | G46: 18 | H46: 25 | K46: 4 - 15 November 2024 : Uji Kompetensi Keahlian Kelas XII (Tahap 1)
...

Sheet Jadwal (2)
A1: JADWAL MENGAJAR SMK NEGERI 3 YOGYAKARTA | R1: F/751/WKS1/-/02
A2: Tahun Pelajaran 2024/2025 | R2: 45483
A4: HARI | B4: JAM KE | C4: 1 | D4: 2 | E4: 3 | F4: 4 | G4: 5 | H4: 6 | I4: 7 | J4: 8 | K4: 9 | L4: 10 | M4: 11 | N4: 12 | P4: Keterangan :
A6: SENIN | B6: Kelas | K6: PSE
B7: Ruang
A8: SELASA | B8: Kelas | C8: PSE | H8: KOMDAT
B9: Ruang
A10: RABU | B10: Kelas | E10: INFORMATIKA
B11: Ruang
A12: KAMIS | B12: Kelas
B13: Ruang
A14: JUM'AT | B14: Kelas | C14: KOMDAT
B15: Ruang
B16: WAKTU PELAJARAN
B17: Senin s.d Kamis | C17: Senin s.d Kamis | F17: Jumat | I17: Catatan :
B18: Tidak Upacara | C18: Upacara : 07.00 - 08.00 | I18: 1. Jangan mengubah jadwal tanpa sepengetahuan Kepala Sekolah
B19: LITERASI | C19: LITERASI | F19: GER TIMUN MAS | I19: 2. Jadwal ini mulai berlaku tanggal
B20: 0. 06.45 - 07.00 | C20: 0. 06.45 - 07.00 | F20: 0. 06.45 - 07.15
B21: 1. 07.00 - 07.45 | C21: 1. 08.00 - 08.40 | F21: 1. 07.15 - 07.55
B22: 2. 07.45 - 08.30 | C22: 2. 08.40 - 09.20 | F22: 2. 07.55 -08.35 | I22: 3. Jumlah jam mengajar ..... jam
B23: 3. 08.30 - 09.15 | C23: 3. 09.20 - 10.00 | F23: 3. 08.35 - 09.15 | I23: 4. Wali kelas ………………..
B24: 4. 09.15 - 10.00 | C24: 4. 10.00 - 10.40 | F24: 4. 09.15 - 19.55
B25: ISTIRAHAT ( 15' ) | C25: ISTIRAHAT ( 15' ) | F25: ISTIRAHAT ( 15' )
B26: 5. 10.15 - 11.00 | C26: 5. 11.05 - 11.45 | F26: 5. 10.10 - 10.50
B27: 6. 11.00 - 11.45 | C27: 6. 11.45 - 12.25 | F27: 6. 10.50 - 11.30
B28: ISTIRAHAT ( 30' ) | C28: ISTIRAHAT (20' ) | F28: SHOLAT JUMAT
B29: 7. 12.15 - 13.00 | C29: 7. 12.45 - 13.20 | F29: 7. 12.30 - 13.10 | J29: ='Kalender Akademik (1)'!L137 -> Yogyakarta, 8 Juli 2024
B30: 8. 13.00 - 13.45 | C30: 8. 13.20- 13.55 | F30: 8. 13.10 - 13.50 | J30: ='Kalender Akademik (1)'!L138 -> Kepala SMK N 3 Yogyakarta
B31: 9. 13.45 - 14.30 | C31: 9. 13.55 - 14.30 | F31: 9. 13.50 - 14.30
B32: 10. 14.30 - 15.15 | C32: 10. 14.30- 15.05 | F32: 10. 14.30- 15.20
B33: ISTIRAHAT ( 15' ) | C33: ISTIRAHAT ( 15' ) | F33: ISTIRAHAT ( 15' )
B34: 11. 15.30 - 16.15 | C34: 11. 15.20 - 16.05 | F34: 11. 15.35 - 16.10 | J34: ='Kalender Akademik (1)'!L142 -> WIDADA, S.Pd., M.Pd.
B35: 12. 16.15 - 17.00 | C35: 12. 16.05 - 16.40 | F35: 12. 16.10 - 16.50 | J35: ='Kalender Akademik (1)'!L143 -> NIP. 196902122000121002

Sheet Prhtngn Mingg Ef(3)
A1: PERHITUNGAN MINGGU EFEKTIF DAN JAM EFEKTIF | H1: F/751/WKS1/-/03
H2: 45483
A3: Program Keahlian | C3: : Teknik Elektronika Industri
A4: Konsentrasi Keahlian | C4: : Elektronika Industri
A5: Mata Pelajaran | C5: : Pemrograman Sistem Embeded
A6: Fase | C6: : F
A7: Kelas | C7: : XI TE 1
A8: Semester | C8: : Gasal
A9: Tahun Pelajaran | C9: : 2024/2025
A11: No. | B11: Bulan | C11: Jml Minggu dalam Semester | D11: Jml Minggu Tidak Efektif | F11: Jml Minggu Efektif | G11: Jml Hari Efektif | H11: Jml Jam Efektif
A12: 1 | B12: JULI | C12: 4 | D12: 3 | F12: 2 | G12: 2 | H12: =G12*4 -> 8
A13: 2 | B13: AGUSTUS | C13: 5 | D13: 1 | F13: 4 | G13: 4 | H13: =G13*4 -> 16
A14: 3 | B14: SEPTEMBER | C14: 4 | D14: 0 | F14: =C14-D14 -> 4 | G14: 4 | H14: =G14*4 -> 16
A15: 4 | B15: OKTOBER | C15: 5 | D15: 0 | F15: =C15-D15 -> 5 | G15: 5 | H15: =G15*4 -> 20
A16: 5 | B16: NOVEMBER | C16: 4 | D16: 1 | F16: 3 | G16: 3 | H16: =G16*4 -> 12
A17: 6 | B17: DESEMBER | C17: 4 | D17: 3 | F17: =C17-D17 -> 1 | G17: 1 | H17: =G17*4 -> 4
A18: Jumlah | C18: =SUM(C12:C17) -> 26 | D18: =SUM(D12:E17) -> 8 | F18: =SUM(F12:F17) -> 19 | G18: =SUM(G12:G17) -> 19 | H18: =SUM(H12:H17) -> 76
B20: Jumlah Jam Pelajaran per Minggu | D20: : | E20: 4 | F20: JP
B21: Jumlah Jam Pelajaran Efektif | D21: : | E21: =H18 -> 76 | F21: JP
B22: Rincian :
B23: a. Tatap Muka | D23: : | E23: =E21-E24-E25 -> 68 | F23: JP
B24: b. UH 14 ( 7 x 2) | D24: : | E24: 4 | F24: JP
B25: c. Ulangan Tengah Semester | D25: : | E25: 4 | F25: JP | Q25: =SUM(Q17:Q24) -> 0
C27: Jumlah | D27: : | E27: =SUM(E23:E26) -> 76 | F27: JP
F32: Yogyakarta, Juli 2024
B34: Koordinator Mapel/KPK | F34: Pendidik,
B38: Taufiq Afandi, S.Pd | F38: ='COVER '!H34 -> Jumari, S.Pd.T., M.Eng
B39: NIP. 197505112006041004 | F39: NIP. 198311152024211006
C41: Mengetahui :
B42: Kepala Sekolah | F42: WKS-1
B46: Widada, S.Pd., M.Pd. | F46: Gunawan S Pd., M Pd
B47: NIP. 196902122000121002 | F47: NIP. 197112132005011004
A72: PERHITUNGAN MINGGU EFEKTIF DAN JAM EFEKTIF | H72: F/751/WKS1/-/27
H73: 45117
A74: Mata Pelajaran | C74: :
A75: Kelas | C75: :
A76: Konsentrasi Keahlian | C76: :
A77: Program Keahlian | C77: :
A78: Fase | C78: :
A79: Semester | C79: :
...

Sheet PROTA (4)
E1: F/751/WKS1/-/04
E2: 45483
C3: PROGRAM TAHUNAN
B5: Program Keahlian | C5: : Teknik Elektronika Industri
B6: Konsentrasi Keahlian | C6: : Elektronika Industri
B7: Mata Pelajaran | C7: ='Prhtngn Mingg Ef(3)'!C5 -> : Pemrograman Sistem Embeded
B8: Fase | C8: : F
B9: Kelas | C9: : XI TE
B10: Semester | C10: : Gasal
B11: Tahun Pelajaran | C11: : 2024/2025
B13: Semester | C13: Elemen/Topik Pembelajaran | D13: Alokasi Waktu ( Jam Pelajaran ) | F13: Jumlah Jam
D14: Kegiatan Tatap Muka | E14: Evaluasi Tiap Kompetensi
B16: GASAL | C16: Memahami Dan Menjelaskan Pemrograman Sistem Embedded. | D16: 8 | F16: =D16+E16 -> 8
C17: Mengidentifikasi dan Mengevaluasi Pin diagram dan fungsi Pinout pada Mikrokontroler Keluarga ATMEGA. | D17: 8 | F17: =D17+E17 -> 8
C18: Mampu Memahami dan Menjelaskan Arsitektur Mikrokontroler Keluarga ATMega. | D18: 8 | F18: =D18+E18 -> 8
C19: Memahami, Mengartikan dan Menerapkan Bahasa Pemrograman C. | D19: 8 | F19: =D19+E19 -> 8
C20: PTS | E20: 4 | F20: =D20+E20 -> 4
B21: 3 | C21: Memahami, Mengartikan dan Menerapkan Bahasa Pemrograman Asembler | D21: 8 | F21: =D21+E21 -> 8
C22: Mengimplementasikan serta Mengoperasikan Software Simulator Offline Proteus. | D22: 8 | F22: =D22+E22 -> 8
C23: Mengimplementasikan, Menerapkan dan Mengoperasikan Software Compiler IDE Arduino. | D23: 10 | F23: =D23+E23 -> 10
C24: Mengimplemantasikan, Menerapkan dan Mengoperasikan Software Compiler AVR | D24: 10 | F24: =D24+E24 -> 10
C25: PAT | E25: 4 | F25: =D25+E25 -> 4
B26: JUMLAH | D26: =SUM(D16:D25) -> 68 | E26: =SUM(E16:E25) -> 8 | F26: =SUM(F16:F25) -> 76
D29: Yogyakarta, Juli 2024
B30: KPK/Koordinator Mapel | D30: Pendidik,
B34: ='Prhtngn Mingg Ef(3)'!B38 -> Taufiq Afandi, S.Pd | D34: ='Prhtngn Mingg Ef(3)'!F38 -> Jumari, S.Pd.T., M.Eng
B35: ='Prhtngn Mingg Ef(3)'!B39 -> NIP. 197505112006041004 | D35: ='Prhtngn Mingg Ef(3)'!F39 -> NIP. 198311152024211006
C37: Mengetahui
B38: Kepala Sekolah | D38: WKS Kurikulum
B42: ='Prhtngn Mingg Ef(3)'!B46 -> Widada, S.Pd., M.Pd. | D42: ='Prhtngn Mingg Ef(3)'!F46 -> Gunawan S Pd., M Pd
B43: ='Prhtngn Mingg Ef(3)'!B47 -> NIP. 196902122000121002 | D43: ='Prhtngn Mingg Ef(3)'!F47 -> NIP. 197112132005011004
C50: PROGRAM TAHUNAN
B51: Program Keahlian | D51: : Teknik Elektronika Industri
B52: Konsentrasi Keahlian | D52: : Elektronika Industri
B53: Mata Pelajaran | D53: : Sistem Kendali Elektronik
B54: Fase | D54: : F
B55: Kelas | D55: : XI TE 1
B56: Semester | D56: : Genap
B57: Tahun Pelajaran | D57: : 2024/2025
B59: Semester | C59: Elemen/Topik Pembelajaran | D59: Alokasi Waktu ( Jam Pelajaran ) | F59: Jumlah Jam
...

Sheet PROSEM(5)  
Z1: F/751/WKS1/-/05
Z2: 45483
B3: PROGRAM SEMESTER
C5: Program Keahlian | E5: : Teknik Elektronika Industri
C6: Konsentrasi Keahlian | E6: : Elektronika Industri
C7: Mata Pelajaran | E7: ='PROTA (4)'!C7 -> : Pemrograman Sistem Embeded
C8: Fase | E8: : F
C9: Kelas | E9: : XI TE 1
C10: Semester | E10: : Gasal
C11: Tahun Pelajaran | E11: : 2024/2025
B13: No | C13: Elemen/Topik Pembelajaran | D13: Jml Jam | E13: Bulan | AE13: Ket.
E14: JULI | I14: AGUSTUS | N14: SEPTEMBER | R14: OKTOBER | W14: NOPEMBER | AA14: DESEMBER
E15: 1 | F15: 2 | G15: 3 | H15: 4 | I15: 1 | J15: 2 | K15: 3 | L15: 4 | M15: 5 | N15: 1 | O15: 2 | P15: 3 | Q15: 4 | R15: 1 | S15: 2 | T15: 3 | U15: 4 | V15: 5 | W15: 1 | X15: 2 | Y15: 3 | Z15: 4 | AA15: 1 | AB15: 2 | AC15: 3 | AD15: 4
B16: 1 | C16: Memahami Dan Menjelaskan Pemrograman Sistem Embedded. | G16: 8
B18: 2 | C18: Mengidentifikasi dan Mengevaluasi Pin diagram dan fungsi Pinout pada Mikrokontroler Keluarga ATMEGA. | H18: 4 | J18: 4
B20: 3 | C20: Mampu Memahami dan Menjelaskan Arsitektur Mikrokontroler Keluarga ATMega. | K20: 4 | M20: 4
B22: 4 | C22: Memahami, Mengartikan dan Menerapkan Bahasa Pemrograman C. | N22: 4 | O22: 4
B25: 5 | C25: PTS | P25: 4
B27: 6 | C27: Memahami, Mengartikan dan Menerapkan Bahasa Pemrograman Asembler | Q27: 4 | R27: 4
B29: 7 | C29: Mengimplementasikan serta Mengoperasikan Software Simulator Offline Proteus. | S29: 4 | T29: 4
B31: 8 | C31: Mengimplementasikan, Menerapkan dan Mengoperasikan Software Compiler IDE Arduino. | U31: 5 | V31: 5
B33: 9 | C33: Mengimplemantasikan, Menerapkan dan Mengoperasikan Software Compiler AVR | X33: 5 | Y33: 5
B35: 10 | C35: PAT | Z35: 4
B37: 11 | C37: Jumlah | G37: =SUM(G16:G36) -> 8 | H37: =SUM(H18:H36) -> 4 | I37: =SUM(I18:I36) -> 0 | J37: =SUM(J18:J36) -> 4 | K37: =SUM(K18:K36) -> 4 | L37: =SUM(L18:L36) -> 0 | M37: =SUM(M18:M36) -> 4 | N37: =SUM(N18:N36) -> 4 | O37: =SUM(O18:O36) -> 4 | ... Z37: =SUM(Z18:Z36) -> 4 | AE37: =SUM(G37:AD38) -> 76
C40: Mengetahui : | D40: WKS-1 | P40: Koord Mapel/KPK | Z40: Pendidik,
C41: Kepala Sekolah
C44: ='PROTA (4)'!B86 -> Widada, S.Pd., M.Pd. | D44: ='PROTA (4)'!D86 -> Gunawan S Pd., M Pd | P44: ='PROTA (4)'!B79 -> Taufiq Afandi, S.Pd | Z44: ='PROTA (4)'!D79 -> Jumari, S.Pd.T., M.Eng
C45: ='PROTA (4)'!B87 -> NIP. 196902122000121002 | D45: ='PROTA (4)'!D87 -> NIP. 197112132005011004 | P45: ='PROTA (4)'!B80 -> NIP. 197505112006041004 | Z45: ='PROTA (4)'!D80 -> NIP. 198311152024211006
B48: PROGRAM SEMESTER
C50: Program Keahlian | E50: : Teknik Elektronika Industri
C51: Konsentrasi Keahlian | E51: : Elektronika Industri
C52: Mata Pelajaran | E52: =E7 -> : Pemrograman Sistem Embeded
C53: Fase | E53: : F
C54: Kelas | E54: : XI TE 1
C55: Semester | E55: : Genap
C56: Tahun Pelajaran | E56: : 2024/2025
B58: No | C58: Elemen/Topik Pembelajaran | D58: Jml Jam | E58: Bulan | AE58: Ket.
E59: Januari | I59: Februari | N59: Maret | R59: April | W59: Mei | AA59: Juni
E60: 1 | F60: 2 | G60: 3 | H60: 4 | I60: 1 | J60: 2 | K60: 3 | L60: 4 | M60: 5 | N60: 1 | O60: 2 | P60: 3 | Q60: 4 | R60: 1 | S60: 2 | T60: 3 | U60: 4 | V60: 5 | W60: 1 | X60: 2 | Y60: 3 | Z60: 4 | AA60: 1 | AB60: 2 | AC60: 3 | AD60: 4
B61: 1 | C61: Memahami sistem kendali terbuka dan sistem kendali tertutup. | D61: 4 | E61: 4
...

Sheet CP (6)
G1: F/751/WKS1/-/06
G2: 45483
B3: CAPAIAN PEMBELAJARAN
B5: Program Keahlian | D5: : Teknik Elektronika Industri
B6: Konsentrasi Keahlian | D6: : Elektronika Industri
B7: Mata Pelajaran | D7: ='PROSEM(5) '!E7 -> : Pemrograman Sistem Embeded
B8: Fase | D8: : F
B9: Kelas | D9: : XI TE 1
B10: Semester | D10: : Gasal
B11: Tahun Pelajaran | D11: : 2024/2025
B12: NO | C12: ELEMEN | E12: CAPAIAN PEMBELAJARAN
B13: 1 | C13: Pemrograman Sistem Embedded | E13: Memahami Dan Menjelaskan Pemrograman Sistem Embedded.
E14: Mengidentifikasi dan Mengevaluasi Pin diagram dan fungsi Pinout pada Mikrokontroler Keluarga ATMEGA.
E15: Mampu Memahami dan Menjelaskan Arsitektur Mikrokontroler Keluarga ATMega.
E16: Memahami, Mengartikan dan Menerapkan Bahasa Pemrograman C.
E17: Memahami, Mengartikan dan Menerapkan Bahasa Pemrograman Asembler
E18: Mengimplementasikan serta Mengoperasikan Software Simulator Offline Proteus.
E19: Mengimplementasikan, Menerapkan dan Mengoperasikan Software Compiler IDE Arduino.
E20: Mengimplemantasikan, Menerapkan dan Mengoperasikan Software Compiler AVR
F23: Yogyakarta, Juli 2024
B24: KPK/Koordinator Mapel | F24: Pendidik,
B28: ='PROTA (4)'!B79 -> Taufiq Afandi, S.Pd | F28: ='PROTA (4)'!D79 -> Jumari, S.Pd.T., M.Eng
B29: ='PROTA (4)'!B80 -> NIP. 197505112006041004 | F29: ='PROTA (4)'!D80 -> NIP. 198311152024211006
B31: ='PROTA (4)'!B82 -> Kepala Sekolah | F31: ='PROTA (4)'!D82 -> WKS Kurikulum
B35: ='PROTA (4)'!B86 -> Widada, S.Pd., M.Pd. | F35: ='PROTA (4)'!D86 -> Gunawan S Pd., M Pd
B36: ='PROTA (4)'!B87 -> NIP. 196902122000121002 | F36: ='PROTA (4)'!D87 -> NIP. 197112132005011004

Sheet Analisis Materi (7)
F1: F/751/WKS1/-/07
F2: 45483
A3: ANALISIS MATERI PEMBELAJARAN
A5: Program Keahlian | C5: : Teknik Elektronika
A6: Konsentrasi Keahlian | C6: : Teknik Elektronika Industri
A7: Mata Pelajaran | C7: ='CP (6)'!D7 -> : Pemrograman Sistem Embeded
A8: Fase | C8: : F
A9: Kelas | C9: : XI TE 1
A10: Semester | C10: : Gasal
A11: Tahun Pelajaran | C11: : 2024/2025
A12: No. | B12: Elemen/Topik Pembelajaran | C12: Kode Profil | D12: Jumlah Jam | E12: Tempat Pembelajaran
E13: Sekolah (Jam.pel) | F13: DU/DI (Jam.pel)
A14: 1 | B14: Memahami Dan Menjelaskan Pemrograman Sistem Embedded. | C14: Elemen 1 | D14: 8 | E14: √
A16: 2 | B16: Mengidentifikasi dan Mengevaluasi Pin diagram dan fungsi Pinout pada Mikrokontroler Keluarga ATMEGA. | C16: Elemen 2 | D16: 8 | E16: √
A18: 3 | B18: Mampu Memahami dan Menjelaskan Arsitektur Mikrokontroler Keluarga ATMega. | C18: Elemen 3 | D18: 8 | E18: √
A20: 4 | B20: Memahami, Mengartikan dan Menerapkan Bahasa Pemrograman C. | C20: Elemen 4 | D20: 8 | E20: √
A23: 5 | B23: Memahami, Mengartikan dan Menerapkan Bahasa Pemrograman Asembler | C23: Elemen 5 | D23: 8 | E23: √
A25: 6 | B25: Mengimplementasikan serta Mengoperasikan Software Simulator Offline Proteus. | C25: Elemen 6 | D25: 8 | E25: √
A27: 7 | B27: Mengimplementasikan, Menerapkan dan Mengoperasikan Software Compiler IDE Arduino. | C27: Elemen 7 | D27: 10 | E27: √
A29: 8 | B29: Mengimplementasikan, Menerapkan dan Mengoperasikan Software Compiler IDE Arduino. | C29: Elemen 8 | D29: 10 | E29: √
A31: 9
A33: 10
A35: 11
D38: Yogyakarta, Juli 2024
B40: Koordinator Mapel/KPK | D40: Pendidik,
B44: ='CP (6)'!B28 -> Taufiq Afandi, S.Pd | D44: ='CP (6)'!F28 -> Jumari, S.Pd.T., M.Eng
B45: ='CP (6)'!B29 -> NIP. 197505112006041004 | D45: ='CP (6)'!F29 -> NIP. 198311152024211006
B46: Mengetahui
B47: ='CP (6)'!B31 -> Kepala Sekolah | D47: ='CP (6)'!F31 -> WKS Kurikulum
B51: ='CP (6)'!B35 -> Widada, S.Pd., M.Pd. | D51: ='CP (6)'!F35 -> Gunawan S Pd., M Pd
B52: ='CP (6)'!B36 -> NIP. 196902122000121002 | D52: ='CP (6)'!F36 -> NIP. 197112132005011004

Sheet ATP (8)
E2: F/751/WKS1/-/08
E3: 45483
A4: ALUR TUJUAN PEMBELAJARAN
A6: Program Keahlian | C6: : Teknik Elektronika
A7: Konsentrasi Keahlian | C7: : Teknik Elektronika Industri
A8: Mata Pelajaran | C8: ='Analisis Materi (7)'!C7 -> : Pemrograman Sistem Embeded
A9: Fase | C9: : F
A10: Kelas | C10: : XI TE 1
A11: Semester | C11: : Gasal
A12: Tahun Pelajaran | C12: : 2024/2025
A14: Alur No | B14: Elemen CP | C14: Topik Pelajaran | D14: Kode | E14: Alokasi Waktu | F14: Semester
A15: 1 | B15: Pemrograman Sistem Embedded | C15: Memahami Dan Menjelaskan Pemrograman Sistem Embedded. | D15: Elemen 1 | E15: 8 | F15: 3
C16: Mengidentifikasi dan Mengevaluasi Pin diagram dan fungsi Pinout pada Mikrokontroler Keluarga ATMEGA. | D16: Elemen 2 | E16: 8 | F16: 3
C17: Mampu Memahami dan Menjelaskan Arsitektur Mikrokontroler Keluarga ATMega. | D17: Elemen 3 | E17: 8 | F17: 3
C18: Memahami, Mengartikan dan Menerapkan Bahasa Pemrograman C. | D18: Elemen 4 | E18: 8 | F18: 3
C19: Memahami, Mengartikan dan Menerapkan Bahasa Pemrograman Asembler | D19: Elemen 5 | E19: 8 | F19: 3
C20: Mengimplementasikan serta Mengoperasikan Software Simulator Offline Proteus. | D20: Elemen 6 | E20: 8 | F20: 3
C21: Mengimplementasikan, Menerapkan dan Mengoperasikan Software Compiler IDE Arduino. | D21: Elemen 7 | E21: 10 | F21: 3
C22: Mengimplementasikan, Menerapkan dan Mengoperasikan Software Compiler IDE Arduino. | D22: Elemen 8 | E22: 10 | F22: 3
C23: JUMLAH | E23: 76
D25: Yogyakarta, Juli 2024
B27: Koordinator Mapel/KPK | D27: Pendidik,
B31: ='Analisis Materi (7)'!B44 -> Taufiq Afandi, S.Pd | D31: ='Analisis Materi (7)'!D44 -> Jumari, S.Pd.T., M.Eng
B32: ='Analisis Materi (7)'!B45 -> NIP. 197505112006041004 | D32: ='Analisis Materi (7)'!D45 -> NIP. 198311152024211006
B33: ='Analisis Materi (7)'!B46 -> Mengetahui
B34: ='Analisis Materi (7)'!B47 -> Kepala Sekolah | D34: ='Analisis Materi (7)'!D47 -> WKS Kurikulum
B38: ='Analisis Materi (7)'!B51 -> Widada, S.Pd., M.Pd. | D38: ='Analisis Materi (7)'!D51 -> Gunawan S Pd., M Pd
B39: ='Analisis Materi (7)'!B52 -> NIP. 196902122000121002 | D39: ='Analisis Materi (7)'!D52 -> NIP. 197112132005011004

Sheet TP (9)
B1: TUJUAN PEMBELAJARAN
C2: Program Keahlian | E2: : Teknik Elektronika Industri | J2: F/751/WKS1/-/09
C3: Konsentrasi Keahlian | E3: : Elektronika Industri | J3: 45483
C4: Mata Pelajaran | E4: ='ATP (8)'!C8 -> : Pemrograman Sistem Embeded
C5: Fase | E5: : F
C6: Kelas | E6: : XI TE 1
C7: Semester | E7: : Gasal
C8: Tahun Pelajaran | E8: : 2024/2025
B10: Alur No | C10: Tujuan Pembelajaran | D10: Kelas/ Semester | E10: Topik Pelajaran | F10: Pemahaman Bermakna | G10: Rencana Asesmen | H10: Model Pembelajaran | I10: Alokasi Waktu | J10: Sumber Belajar | K10: Ket.
A16: x
J25: Yogyakarta, Juli 2024
C26: Mengetahui :
C27: Kepala Sekolah | E27: WKS 1 | G27: Koord Mapel/KPK | J27: Pendidik,
C31: ='PROSEM(5) '!C89 -> Widada, S.Pd., M.Pd. | E31: ='PROSEM(5) '!D89 -> Gunawan S Pd., M Pd | G31: ='PROSEM(5) '!P89 -> Taufiq Afandi, S.Pd | J31: ='PROSEM(5) '!Z89 -> Jumari, S.Pd.T., M.Eng
C32: ='PROSEM(5) '!C90 -> NIP. 196902122000121002 | E32: ='PROSEM(5) '!D90 -> NIP. 197112132005011004 | G32: ='PROSEM(5) '!P90 -> NIP. 197505112006041004 | J32: ='PROSEM(5) '!Z90 -> NIP. 198311152024211006

Sheet KKTP (10)
D1: F/751/WKS1/-/10
D2: 45117
B5: ANALISA PENGHITUNGAN KKTP | G5: NO | H5: Kemampuan Akhir Fase | I5: Tujuan Pembelajaran | J5: Kriteria Ketercapaian Tujuan Pembelajaran | N5: Tindak Lanjut
B6: KRITERIA KETERCAPAIAN TUJUAN PEMBELAJARAN | J6: Baru Berkembang | K6: Layak | L6: Cakap | M6: Mahir
B7: TH 2024 - 2025 | J7: 0 – 40% | K7: 41 – 74 % | L7: 75 – 85% | M7: 86 – 100%
B10: NAMA SEKOLAH | C10: :
B11: BIDANG KEAHLIAN | C11: :
B13: PROGRAM KEAHLIAN | C13: :
B15: KONSENTRASI KEAHLIAN | C15: :
B18: NAMA MATA PELAJARAN | C18: :
B19: KELAS/ FASE | C19: :
B20: ALOKASI JAM PELAJARAN TOTAL | C20: :
B21: ALOKASI JP PROJEK (P5) | C21: :
B22: DURASI PEMBELAJARAN TIAP PERTEMUAN | C22: :
B25: NAMA ELEMEN CAPAIAN PEMBELAJARAN | C25: :
B26: URUTAN ELEMEN | C26: :
B27: MATERI/ KONTEN PEMBELAJARAN | C27: :
B32: KEMAMPUAN AKHIR FASE | C32: :
N42: Yogyakarta, Juli 2024
G43: Mengetahui :
G44: Kepala Sekolah | I44: WKS 1 | J44: Koord Mapel/KPK | N44: Pendidik,
G48: ='TP (9)'!C31 -> Widada, S.Pd., M.Pd. | I48: ='TP (9)'!E31 -> Gunawan S Pd., M Pd | J48: ='TP (9)'!G31 -> Taufiq Afandi, S.Pd | N48: ='TP (9)'!J31 -> Jumari, S.Pd.T., M.Eng
G49: ='TP (9)'!C32 -> NIP. 196902122000121002 | I49: ='TP (9)'!E32 -> NIP. 197112132005011004 | J49: ='TP (9)'!G32 -> NIP. 197505112006041004 | N49: ='TP (9)'!J32 -> NIP. 198311152024211006

Sheet KKM (8) batal
I1: F/751/WKS1/-/32
I2: 41783
A3: ANALISA PENGHITUNGAN KKTP
A4: SMK N 3 YOGYAKARTA
A5: TH 2023 - 2024
A6: NAMA SEKOLAH | B6: : SMK NEGERI 3 YOGYAKARTA
A7: MATA PELAJARAN | B7: :
A8: KELAS | B8: :
A9: FASE | B9: :
B11: :
A12: ALOKASI WAKTU
A13: Contoh:
A14: KOMPETENSI DASAR/ CAPAIAN PEMBELAJARAN | B14: INDIKATOR / MATERI POKOK | C14: INTAKE | D14: KOMPLEKSITAS | E14: DAYA DUKUNG | F14: SKM
F15: INDIKATOR | G15: KD/CP | H15: MATA PELAJARAN | I15: KET.
C16: 1 | D16: 2 | E16: 3 | F16: =SUM(C16:E18)/9*100 -> 66.666667 | G16: =(F16+F19)/2 -> 72.222222
C19: 2 | D19: 2 | E19: 3 | F19: =SUM(C19:E21)/9*100 -> 77.777778
A22: Koordinator Mapel | I22: Yogyakarta, Juli 2022
I23: Pendidik
C26: Mengetahui :
A27: Kepala Sekolah | I27: Waka Kurikulum
A31: Drs. B. Sabri | I31: Maryuli Darmawan, S.Pd. M.Eng
A32: NIP. 19630830 198703 1 003 | I32: NIP. 19700720 199802 1 003

Sheet MA- LKPD (11)
H1: F/751/WKS1/-/11
H2: 45483
A3: MODUL AJAR DAN LKPD

Sheet Daft Hdr (12)
M1: F/751/WKS1/-/12
M2: 45483
A3: DAFTAR HADIR
A5: Mata Pelajaran | C5: ='Analisis Materi (7)'!C7 -> : Pemrograman Sistem Embeded | I5: Wali Kelas | N5: : Jumari, S.Pd.T., M.Eng
A6: Kelas | C6: : XI TE 1 | I6: Semester | N6: : Gasal
A7: Konsentrasi Keahlian | C7: : Teknik Elektronika | I7: Tahun Pelajaran | N7: : 2024 / 2025
A9: No. | B9: NIS | C9: NAMA | D9: L/P | E9: Pertemuan ke / Tanggal
E10: 18, 7 | F10: 25, 7 | G10: 8 ,8 | H10: 15, 8 | I10: 22, 8 | J10: 29, 8 | K10: 5, 9 | L10: 12, 9
E11: 1 | F11: 2 | G11: 3 | H11: 4 | I11: 5 | J11: 6 | K11: 7 | L11: 8 | M11: 9 | N11: 10 | O11: 11 | P11: 12 | Q11: 14 | R11: 15 | S11: 16 | T11: 17
A12: 1 | B12: 0078276901 | C12: Abdu Rasyid 'Athaa | D12: L | E12: v | F12: v | G12: v | H12: v | I12: v | J12: v | K12: v | L12: v
A13: 2 | B13: 0067470379 | C13: Abu Daffa Al-Dzulfikar Ali | D13: L | E13: v | F13: v | G13: v | H13: v | I13: v | J13: v | K13: v | L13: v
A14: 3 | B14: 0072903809 | C14: Adhitya Kurniawan | D14: L | E14: v | F14: v | G14: v | H14: v | I14: v | J14: v | K14: v | L14: v
A15: 4 | B15: 0076549407 | C15: Aditya Febriano | D15: L | E15: v | F15: v | G15: v | H15: v | I15: v | J15: v | K15: v | L15: v
A16: 5 | B16: 0069904338 | C16: Aditya Rendra Wardana | D16: L | E16: v | F16: v | G16: v | H16: v | I16: v | J16: v | K16: v | L16: v
A17: 6 | B17: 0084404661 | C17: Ahmad 'Izzuddin Ramadani | D17: L | E17: v | F17: v | G17: v | H17: s | I17: v | J17: v | K17: v | L17: v
A18: 7 | B18: 0073394500 | C18: Alrafif Megannanda Hermawan | D18: L | E18: v | F18: A | G18: v | H18: v | I18: v | J18: v | K18: v | L18: v
A19: 8 | B19: 0064104410 | C19: Aziz Qurrahman | D19: L | E19: S | F19: v | G19: v | H19: v | I19: v | J19: S | K19: v | L19: v
A20: 9 | B20: 0078004181 | C20: Bagus Imam Santoso | D20: L | E20: v | F20: v | G20: v | H20: v | I20: v | J20: v | K20: v | L20: v
A21: 10 | B21: 0066065365 | C21: Bayo Ikbar Muhammad Arkan | D21: L | E21: v | F21: v | G21: v | H21: v | I21: v | J21: v | K21: v | L21: v
A22: 11 | B22: 0066626041 | C22: Bramantya Maheswara Saputra | D22: L | E22: S | F22: v | G22: S | H22: v | I22: v | J22: S | K22: v | L22: v
A23: 12 | B23: 0062007118 | C23: Brian Rasya Azahra | D23: L | E23: v | F23: v | G23: v | H23: v | I23: v | J23: v | K23: v | L23: v
... A47: 36 | B47: 0057167888 | C47: Ardan Kris Apriyanendra | D47: L | E47: A | F47: v | G47: A | H47: A | I47: A | J47: A | K47: A | L47: A
I49: Yogyakarta, …………………
I50: Pendidik,
I54: Jumari, S.Pd.T., M.Eng
I55: NIP. 198311152024211000

Sheet Penanganan Pesdik Brmslh (13)
F1: F/751/WKS1/-/13
F2: 45483
A3: PENANGANAN PESERTA DIDIK BERMASALAH
A5: Mata Pelajaran : | D5: Kelas/Semester : Gasal | F5: Tahun Pelajaran : 2024/2025
A7: NO | B7: NAMA PESERTA DIDIK | C7: MASALAH YANG DIHADAPI | D7: TANGGAL | E7: PENYELESAIAN MASALAH | F7: TANDA TANGAN SISWA
F31: Yogyakarta, Juli 2024
B32: Mengetahui :
B33: Kepala Sekolah | C33: WKS 1 | E33: Koord Mapel/KPK | F33: Pendidik,
B37: ='KKTP (10)'!G48 -> Widada, S.Pd., M.Pd. | C37: ='KKTP (10)'!I48 -> Gunawan S Pd., M Pd | E37: ='KKTP (10)'!J48 -> Taufiq Afandi, S.Pd | F37: ='KKTP (10)'!N48 -> Jumari, S.Pd.T., M.Eng
B38: ='KKTP (10)'!G49 -> NIP. 196902122000121002 | C38: ='KKTP (10)'!I49 -> NIP. 197112132005011004 | E38: ='KKTP (10)'!J49 -> NIP. 197505112006041004 | F38: ='KKTP (10)'!N49 -> NIP. 198311152024211006

Sheet FORMATIF (14)
AM1: F/751/WKS1/-/14
A2: LEMBAR PENILAIAN FORMATIF | AM2: 45117
A4: Mata Pelajaran : | F4: Kelas : | L4: Konsentrasi Keahlian : | X4: Semester : ……….. | AF4: Tahun Pelajaran : ……….
A6: NO | B6: Nama Siswa | C6: KURIKULUM MERDEKA
C7: ELEMEN | D7: 1 | G7: 2 | J7: 3 | M7: 4 | P7: 5 | S7: 6 | V7: 7 | Y7: 8 | AB7: 9 | AE7: PTS | AH7: PAS/PAT | AK7: RERATA | AN7: NA | AO7: PREDIKAT
C8: Tgl/bln
C9: NILAI | D9: NH | E9: R/P | F9: NA | G9: NH | H9: R/P | I9: NA | J9: NH | K9: R/P | L9: NA | M9: NH | N9: R/P | O9: NA | P9: NH | Q9: R/P | R9: NA | S9: NH | T9: R/P | U9: NA | V9: NH | W9: R/P | X9: NA | Y9: NH | Z9: R/P | AA9: NA | AB9: NH | AC9: R/P | AD9: NA | AE9: NH | AF9: R/P | AG9: NA | AH9: NH | AI9: R/P | AJ9: NA
A10: 1
A11: 2
A12: 3
A13: 4
A14: 5
A15: 6
A16: 7
A17: 8
A18: 9
A19: 10
A20: 11
A21: 12
... A41: 32
B43: Mengetahui | N43: Klasifikasi | AJ43: Yogyakarta, …………………………
B44: KP/Koord Mapel | E44: Ket : | N44: A | O44: ( 96 s/d 100 ) | S44: C+ | T44: ( 70 s/d 74 ) | Z44: NILAI RERATA | AJ44: Pendidik
E45: NH | G45: : | H45: Nilai Harian | N45: A- | O45: ( 91 s/d 95 ) | S45: C | T45: ( 65 s/d 69 ) | Y45: LPK.P = _____________ X 4
E46: R/P | G46: : | H46: Remidi/Pengayaan | N46: B+ | O46: ( 86 s/d 90 ) | S46: C- | T46: ( 60 s/d 64 ) | Z46: 100
B47: …………………………….. | E47: Penilaian dalam bentuk Angka Puluhan | N47: B | O47: ( 81 s/d 85 ) | S47: D+ | T47: ( 55 s/d 59 )
B48: NIP. ……………………… | N48: B- | O48: ( 75 s/d 80 ) | S48: D+ | T48: ( Kurang dari 54 ) | AJ48: NIP.

Sheet NILAI KETRAMPILAN (12.b)
AQ1: F/751/WKS1/37
A2: LEMBAR PENILAIAN KETRAMPILAN (K-4) | AQ2: 41783
A4: Mata Pelajaran : | F4: Kelas : | L4: Konsentrasi Keahlian : | W4: Semester : ………… | AA4: Tahun Pelajaran : …………… / ……………
A6: NO | B6: Nama Siswa | C6: KURIKULUM MERDEKA
C7: KD KE- | D7: 4.1 | G7: 4.2 | J7: 4.3 | M7: 4.4 | P7: 4.5 | S7: 4.6 | V7: 4.7 | Y7: 4.8 | AB7: 4.9 | AE7: 4.10 | AH7: 4.11 | AK7: 4.12 | AN7: RERATA | AQ7: Nilai Lap Pencap Komp. Ketrampiln (LPK.K) | AR7: PREDIKAT
C8: Tgl/bln
C9: NILAI | D9: NPr | E9: NPj | F9: Npo | G9: NPr | H9: NPj | I9: Npo | J9: NPr | K9: NPj | L9: Npo | M9: NPr | N9: NPj | O9: Npo | P9: NPr | Q9: NPj | R9: Npo | S9: NPr | T9: NPj | U9: Npo | V9: NPr | W9: NPj | X9: Npo | Y9: NPr | Z9: NPj | AA9: Npo | AB9: NPr | AC9: NPj | AD9: Npo | AE9: NPr | AF9: NPj | AG9: Npo | AH9: NPr | AI9: NPj | AJ9: Npo | AK9: NPr | AL9: NPj | AM9: Npo
A10: 1
A11: 2
A12: 3
A13: 4
A14: 5
A15: 6
A16: 7
A17: 8
A18: 9
A19: 10
A20: 11
A21: 12
... A41: 32
B43: Mengetahui | N43: Klasifikasi | AN43: Yogyakarta, ……………….
B44: K3/Koord Mapel | E44: Ket : | N44: A | O44: ( 96 s/d 100 ) | S44: C+ | T44: ( 70 s/d 74 ) | AC44: NILAI RERATA | AN44: Pendidik
E45: Npr | G45: : | H45: Nilai Praktek | N45: A- | O45: ( 91 s/d 95 ) | S45: C | T45: ( 65 s/d 69 ) | AB45: LPK.K = _____________ X 4
E46: Npj | G46: : | H46: Nilai Projek | N46: B+ | O46: ( 86 s/d 90 ) | S46: C- | T46: ( 60 s/d 64 ) | AC46: 100
B47: …………………………….. | E47: Npo | G47: : | H47: Nilai Portopolio | N47: B | O47: ( 81 s/d 85 ) | S47: D+ | T47: ( 55 s/d 59 )
B48: NIP. ……………………… | F48: Penilaian dalam Angka Puluhan | N48: B- | O48: ( 75 s/d 80 ) | S48: D+ | T48: ( Kurang dari 54 ) | AN48: NIP.
F50: Ket :
H51: 1 | I51: : | J51: Tidak Terampil
H52: 2 | I52: : | J52: Terampil Praktek Dengan Banyak bantuan Pembimbing
H53: 3 | I53: : | J53: Trampil Praktek Dengan Sedikit Bantuan pembimbing
H54: 4 | I54: : | J54: Trampil Praktek TaNKa Bantuan pembimbing

Sheet Sheet1

Sheet Analisis Kebutuhan Alat(15)
F1: F/751/WKS1/15
F2: 45117
A3: ANALISIS KEBUTUHAN ALAT
A6: NO | B6: KD | C6: NAMA ALAT/BAHAN | D6: SPESIFIKASI | E6: VOLUME | F6: KETERANGAN
F18: Yogyakarta,
B19: Mengetahui :
B20: KP/Koordinator Mapel | F20: Pendidik,
B25: NIP. | F25: NIP.
B27: Kepala SMK Negeri 3 Yogyakarta, | F27: Waka Kurikulum
B32: Drs. B. Sabri | F32: Maryuli Darmawan, S.Pd. M.Eng
B33: NIP. 1963 0830 198703 1 003 | F33: NIP. 19700720 199802 1 003

Sheet Buku Pegangan (16)
E1: F/751/WKS1/-/16
E2: 45117
A3: DAFTAR BUKU PEGANGAN
A5: Mata Pelajaran | C5: :
A6: Kelas | C6: :
A7: Konsentrasi Keahlian | C7: :
A8: Program Studi Keahlian | C8: :
A9: Tahun Pelajaran | C9: :
A11: A | B11: PEGANGAN PENDIDIK
A13: No. | B13: Judul Buku | C13: Pengarang | D13: Penerbit | E13: Tahun
A27: B | B27: PEGANGAN PESERTA DIDIK
A29: No. | B29: Judul Buku | C29: Pengarang | D29: Penerbit | E29: Tahun
A31: 1
D36: Yogyakarta,
B37: Mengetahui :
B38: KP/Koordinator Mapel | D38: Pendidik,
B43: NIP. | D43: NIP.
B45: Kepala SMK Negeri 3 Yogyakarta, | D45: Waka Kurikulum
B49: Drs. B. Sabri | D49: Maryuli Darmawan, S.Pd. M.Eng
B50: NIP. 1963 0830 198703 1 003 | D50: NIP. 19700720 199802 1 003

Sheet Kisi-Kisi (17)
F1: F/751/WKS1/-/17
F2: 45117
A3: KISI-KISI PENYUSUNAN SOAL EVALUASI
A5: Mata Pelajaran : Sistem Kendali Elektronika | D5: Tahun Pelajaran : 2023 / 2024 | E5: Jumlah Soal : 35
A6: Kelas : XI TE 1 | D6: Bentuk Soal : a. Obyektif Tes | E6: Waktu : 90 Menit
A7: Konsentrasi Keahlian : Elektronika Industri
A9: NO | B9: KOMPETENSI DASAR | C9: JUMLAH SOAL | D9: URAIAN MATERI | E9: INDIKATOR | F9: NO SOAL | G9: KUNCI JAWABAN
A10: 1 | B10: Menjabarkan konsep sistem kendali elektronik | C10: 1 | D10: Mendeskripsikan konsep system kendali elektronik open loop dan close loop. | E10: Disajikan teks, peserta didik dapat mendeskripsikan konsep sistem kendali elektronik | F10: 1
A11: 2
A12: 3 | C12: 1 | D12: Mendeskripsikan fungsi - fungsi pada block diagram sistem kendali open loop dan close loop. | E12: Disajikan teks dan gambar, peserta didik dapat mendeskripsikan tugas dari masing – masing fungsi pada block diagram open loop dan close loop. | F12: 2
A13: 4
A14: 5
A15: 6 | C15: 1 | D15: Mendeskripsikan konsep system kendali elektronik open loop dan close loop. | E15: Disajikan teks, peserta didik dapat mendeskripsikan konsep sistem kendali elektronik | F15: 3
A16: 7
A17: 8 | C17: 1 | D17: Menerapkan penggunaan konsep sistem kendali elektronika open loop dan close loop pada kehidupan sehari – hari. | E17: Disajikan teks, peserta didik dapat menyimpulkan fungsi dan memberikan contoh penggunaan konsep sistem kendali elektronik open loop dan close loop. | F17: 4
A18: 9
A19: 10
A20: 11
A21: 12 | C21: 1 | D21: Mendeskripsikan control PID dalam sistem kendali elektronik. | E21: Disajikan teks, peserta didik dapat mendeskripsikan kontrol PID. | F21: 5
A22: 13
A23: 14 | C23: 1 | D23: Menerapkan penggunaan konsep sistem kendali elektronika open loop dan close loop pada kehidupan sehari – hari. | E23: Disajikan teks, peserta didik dapat menyimpulkan fungsi dan memberikan contoh penggunaan konsep sistem kendali elektronik open loop dan close loop. | F23: 6
A24: 15
A25: 16
A26: 17
A27: 18 | D27: Mendeskripsikan fungsi - fungsi pada block diagram sistem kendali open loop dan close loop. | E27: Disajikan teks dan gambar, peserta didik dapat mendeskripsikan tugas dari masing – masing fungsi pada block diagram open loop dan close loop. | F27: 7
A28: 19
A29: 20
A30: 21
A31: 22 | D31: Menyimpulkan keuntungan penggunaan sistem kendali elektronik dibanding sistem kendali mekanik (manual) | E31: Disajikan teks, peserta didik dapat menyimpulkan keuntungan penggunaan sistem kendali elektronik dibanding sistem kendali mekanik (manual) | F31: 8
A32: 23
A33: 24
A34: 25
A35: 26
A36: 27 | D36: Menjabarkan fungsi kaki Op-Amp LM741. | E36: Disajikan teks dan gambar, Op-Amp LM741, peserta didik mampu mengidentifikasi fungsi kaki Op-Amp LM741 | F36: 9 | L36: Mengetahui :
A37: 28 | L37: Kepala SMK Negeri 3 Yogyakarta, | Q37: Yogyakarta, ……………………………..
A38: 29 | Q38: Pendidik,
A39: 30
A40: 31 | D40: Menjabarkan fungsi kaki Op-Amp LM741. | E40: Disajikan teks dan gambar, Op-Amp LM741, peserta didik mampu mengidentifikasi fungsi kaki Op-Amp LM741 | F40: 10 | L40: Drs. Bujang Sabri
A41: 32 | L41: NIP. 19630830 198703 1 003 | Q41: ………………………………………………
A42: 33 | Q42: NIP. ………………………………………..
...

Sheet Anailis Hasil Ulangan (18)
H1: F/751/WKS1/-/18
H2: 45117
A4: ANBUSO TERLAMPIR
A5: Tidak Wajib semua mapel/ Non Mapel UN pakai Manual saja

Sheet Anl daya serap Hsl Ev (19)
AB1: F/84/WKS1/-/19
AB2: 45117
A3: ANALISIS KETUNTASAN DAN DAYA SERAP
A5: Mata Pelajaran | C5: : …….. | M5: Kelas/Semester | S5: : ………… | W5: KKTP | Z5: : …………….
A6: Bentuk Soal | C6: : …….. | M6: Jml Peserta Didik | S6: : ………… | W6: Tanggal Evaluasi | Z6: : …………….
A7: Jumlah Soal | C7: : …….. | M7: Elemen | S7: : …………
A9: NO | B9: NAMA | C9: NOMOR DAN BOBOT SOAL | S9: JML SKOR | T9: NILAI | U9: TERCAPAI (%) | V9: TUNTAS
W11: Keterangan :
A12: 1 | W12: 1 | X12: a. Nilai = Skor yg diperoleh X 100
A13: 2 | Y13: Total skor
A14: 3
A15: 4 | X15: b. Ketuntasan Klasikal = Jml Peserta Didik yg Tuntas x 100%
A16: 5 | Z16: Jml Peserta Didik
A17: 6 | W17: 2 | X17: Peserta didik disebut TUNTAS belajar jika telah menguasai bahan
A18: 7 | X18: (ketercapaian belajarnya) ≥ KKM
A19: 8 | W19: 3 | X19: Kelas disebut TUNTAS belajar jika Peserta Didik yang TUNTAS mencapai ≥ 85%
A20: 9
A21: 10
A22: 11 | W22: 4 | X22: a. Jumlah Peserta Didik | AB22: : ……
A23: 12 | X23: b. Jumlah Tuntas | AB23: : ……
A24: 13 | X24: c. Jumlah tidak tuntas | AB24: : ……
A25: 14 | X25: d. Ketuntasan Klasikal | Z25: : …... %
A26: 15 | X26: e. Secara Klasikal | Z26: : Tuntas / Tidak Tuntas
A27: 16 | W27: 5 | X27: Daya Serap =
A28: 17 | Y28: Isi rumus mencari Daya Serap dan ketentuannya
A29: 18
A30: 19
A31: 20
A32: 21 | W32: Kesimpulan :
A33: 22 | W33: 1 | X33: Perlu perbaikan secara klasikal untuk soal
A34: 23 | X34: nomor : ……………………………………………………..
A35: 24 | W35: 2 | X35: Perlu program perbaikan secara individual
A36: 25 | X36: untuk Peserta Didik nomor
A37: 26 | X37: …………………………………..
A38: 27 | W38: 3 | X38: Perlu program pengayaan untuk
A39: 28 | X39: Peserta Didik nomor
A40: 29
A41: 32
B43: Mengetahui : | T43: Yogyakarta, ………………
B44: Kepala Sekolah | T44: Pendidik,
...

Sheet Prg. Perb.&pengyn(20)
H1: F/751/WKS1/-/20
H2: 45117
A3: PROGRAM PERBAIKAN / PENGAYAAN
A4: Tahapan :
A5: 1. Analisis Ketuntasan Belajar
A6: 2. Melakukan Pembinaan/Pengarahan sesuai dengan jenis kesukaran
A7: 3. Pemberian Tugas / Materi Perbaikan / Pengayaan
A8: 4. Pemberian Nilai Perbaikan / Pengayaan
A10: 1. Perhitungan Ketuntasan Belajar
A11: Mata Pelajaran | C11: : ……………
A12: Kelas/Program | C12: : ……………
A13: Kompetensi Dasar | C13: : ……………
A14: Tanggal Tes | C14: : ……………
B16: NILAI (INTERVAL) | D16: JUMLAH SISWA | F16: KETERANGAN
B17: N < 75 | F17: Mengikuti Perbaikan
B18: N > 75 | F18: Mengikuti Pengayaan
A21: 2. Sebelum mendapat tugas, peserta didik mendapat arahan/bimbingan berupa jenis kesukaran
A23: NO | B23: NAMA | D23: NILAI | E23: KESUKARAN | H23: KETERANGAN
A24: 1
A25: 2
A26: 3
A27: 4
A28: 5
A29: 6
A30: 7
A31: 8
A32: 9
A33: 10
A34: 11
A35: 12
... A37: 14
A38: 3. Setelah mendapat bimbingan siswa mendapat tugas
A39: a. Remedial / PR soal nomor ……………………………….*)
A40: b. Membuat ringkasan / ikhtisar materi tentang ………………
A41: c. Mengerjakan soal berikutnya
A42: d. …………………………….
A43: *) Sebut jenis dan bukti fisiknya dilampirkan
A44: 4. Data peserta didik yang mendapat nilai Perbaikan / Pengayaan
A46: NO | B46: NAMA | D46: NILAI | H46: KETERANGAN
D47: Sebelum Perbaikan | E47: Setelah Perbaikam
...

Sheet Prog. Pengayaan(21)
H1: F/751/WKS1/-/21
H2: 45117
A3: PROGRAM PENGAYAAN
A4: Tahapan :
A5: 1. Analisis Ketuntasan Belajar
A6: 2. Melakukan Pembinaan/Pengarahan sesuai dengan jenis kesukaran
A7: 3. Pemberian Tugas / Materi Perbaikan / Pengayaan
A8: 4. Pemberian Nilai Perbaikan / Pengayaan
A10: 1. Perhitungan Ketuntasan Belajar
A11: Mata Pelajaran | C11: : ……………
A12: Kelas/Program | C12: : ……………
A13: Kompetensi Dasar | C13: : ……………
A14: Tanggal Tes | C14: : ……………
B16: NILAI (INTERVAL) | D16: JUMLAH SISWA | F16: KETERANGAN
B17: N < 75 | F17: Mengikuti Perbaikan
B18: N > 75 | F18: Mengikuti Pengayaan
A20: 2. Sebelum mendapat tugas pengayaan, peserta didik mendapat arahan/bimbingan.
A22: NO | B22: NAMA | D22: NILAI | E22: JENIS ARAHAN/BIMBINGAN | H22: KETERANGAN
A23: 1
A24: 2
A25: 3
A26: 4
A27: 5
A28: 6
A29: 7
A30: 8
A31: 9
A32: 10
A33: 11
A34: 12
... A36: 14
A37: 3. Setelah mendapat bimbingan siswa mendapat tugas
A38: a. Membuat ringkasan / ikhtisar materi tentang ………………………………………...……….*)
A39: b. Mengerjakan soal berikutnya
A40: c. …………………………….
A41: *) Sebut jenis dan bukti fisiknya dilampirkan
A42: 4. Data peserta didik yang mendapat nilai Pengayaan
A44: NO | B44: NAMA | D44: NILAI | H44: KETERANGAN
D45: Sebelum Perbaikan | E45: Setelah Perbaikam
E46: Tgl. ……. | F46: Tgl. ……. | G46: Tgl. …….
...

Sheet Agenda  (22)
F1: F/751/WKS1/-/22
A2: AGENDA HARIAN | F2: 45117
A4: Nama | C4: : | E4: Kelas :
A5: NIP. | C5: : | E5: Tahun Pelajaran :
A6: Mata Pelajaran | C6: :
A8: Hari/Tgl | B8: Kelas | C8: Jam | D8: Materi yang disampaikan (Elemen) | E8: No.RPP/MA | F8: Keterangan
A56: Hari/Tgl | B56: Kelas | C56: Jam | D56: Materi yang disampaikan (SK/KD) | E56: No.RPP/MA | F56: Keterangan
E97: Yogyakarta,
A99: Koordinator Mapel | E99: Pendidik,
A104: NIP. | E104: NIP.
D107: Mengetahui :
A108: Kepala Sekolah | E108: WKS 1
A112: Drs. B. Sabri | E112: Maryuli Darmawan, S.Pd. M.Eng
A113: NIP. 19630830 198703 1 003 | E113: NIP. 19700720 199802 1 003

Sheet Target&Capaian Kur ( (23)
M1: F/84/WKS1/-/23
M2: 45117
B3: TARGET DAN PENCAPAIAN TARGET KURIKULUM
B5: Mata Pelajaran | E5: :
B6: Konsentrasi Keahlian | E6: :
B7: Program Keahlian | E7: :
B8: Fase | E8: :
B9: Kelas | E9: :
B10: Semester | E10: :
B11: Tahun Pelajaran | E11: :
C12: 100 | G12: Contoh
C13: 95
C14: 90
C15: 85
C16: 80
C17: 75
C18: 70
C19: 65
C20: 60
C21: 55
C22: 50
C23: 45
C24: 40
... C30: 10
C31: 5 | D31: 0.06
C32: 0
D33: Jul | E33: Ags | F33: Sept | G33: Okt | H33: Nov | I33: Des | J33: Jan | K33: Feb | L33: Mar | M33: Apr | N33: Mei | O33: Jun
B34: Keterangan :
B35: Target Kurikulum =
B36: Jumlah jam pelajaran yang harus diselesaikan | K36: x | L36: 1 | N36: (tampilan berupa histogram)
B37: Jumlah jam pelajaran yang harus diselesaikan dalam satu tahun
B39: Pencapaian Target Kurikulum :
B40: Jumlah jam pelajaran yang sudah diselesaikan | K40: x | L40: 1 | N40: (tampilan berupa diagram garis)
B41: Jumlah jam pelajaran yang harus diselesaikan dalam satu tahun
B42: Catatan :
K44: Yogyakarta, Juli 2019
B45: Mengetahui :
B46: KP/Koordinator Mapel | K46: Pendidik,
B50: NIP. | K50: NIP.
B52: Kepala Sekolah | K52: Waka Kurikulum
...

Sheet AJP (22)
E1: F/751/WKS1/-/47
B2: contoh: | E2: 41783
A3: ANALISIS JAM PEMBELAJARAN
A5: Mata Pelajaran | C5: :
A6: Kelas | C6: :
A7: Konsentrasi Keahlian | C7: :
A8: Program Keahlian | C8: :
A9: Fase | C9: :
A10: Tahun Pelajaran | C10: :
A12: No. | B12: Standar Kompetensi/Kompetensi Dasar | C12: Kode Profil | D12: Jumlah Jam | E12: Tempat Pembelajaran
E13: Sekolah (Jam.pel) | F13: DU/DI (Jam.pel)
A14: 1. | B14: TURUNAN FUNGSI ALJABAR
B15: 3.31 Menentukan turunan fungsi aljabar menggunakan definisi limit fungsi atau sifat-sifat turunan fungsi serta penerapannya
B16: 3.32 Menganalisis keberkaitan turunan pertama fungsi dengan nilai maksimum, nilai minimum, dan selang kemonotonan fungsi, serta kemiringan garis singgung kurva
A17: 2. | B17: INTEGRAL
B18: 3.33 Menentukan nilai integral tak tentu dan tertentu fungsi aljabar
B19: 3.34 Menentukan luas permukaan dan volume benda putar dengan menggunakan integral tertentu
B21: JUMLAH | D21: =SUM(D14:D20) -> 0 | E21: =SUM(E14:E20) -> 0
C23: Yogyakarta, Juli
B24: Mengetahui :
B25: KP/Koordinator Mapel | C25: Pendidik,
B30: NIP. | C30: NIP.
B32: Kepala Sekolah | C32: WKS 1
B36: Drs. B Sabri | C36: Maryuli Darmawan, S.Pd. M.Eng
B37: NIP. 19630830 198703 1 003 | C37: NIP. 19700720 199802 1 003

Sheet Analisis SKM (8)
M1: F/751/WKS1/-/32
M2: 43636
A3: ANALISIS SKM SESUAI DENGAN SILABUS KURIKULUM 2013
A4: MATA PELAJARAN................
A5: NO | B5: KOMP. DASAR | C5: IPK | D5: SKM IPK | H5: SKM MATERI POKOK | L5: SKM KOMP. DASAR | M5: SKM MAPEL | N5: KET
D6: Kompl | E6: Daya Duk | F6: Input | G6: SKM | H6: Kompl | I6: Daya Duk | J6: Input | K6: SKM
A7: 1 | B7: 3.1 dan 4.1 | C7: 1
C8: 2
C9: 3
A11: 2 | B11: 3.2 dan 4.2 | C11: 1
C12: 2
C13: 3
A15: 3 | B15: 3.3 dan 4.3 | C15: 1
C16: 2
C17: 1
C18: 2
B19: dst
L22: Yogyakarta, Juli 2019
B23: Mengetahui :
B24: KP/Koordinator Mapel | L24: Pendidik,
B29: NIP. | L29: NIP.
B31: Kepala Sekolah | L31: WKS 1
B35: Drs. B Sabri | L35: Maryuli Darmawan, S.Pd. M.Eng
B36: NIP. 19630830 198703 1 003 | L36: NIP. 19700720 199802 1 003

Sheet Rencana Penilaian (24)
K1: F/751/WKS1/-/24
K2: 45117
A4: PERENCANAAN PENILAIAN
A5: SMK NEGERI 3 YOGYAKARTA TAHUN PELAJARAN 2022 - 2023
A6: Paket Keahlian | C6: :
A7: Mata Pelajaran | C7: :
A8: Kelas | C8: :
A9: Semester | C9: :
A12: NO | B12: ELEMEN | C12: P1 | D12: P2 | E12: P3 | F12: P4 | G12: P5 | H12: P6 | I12: P7 | J12: P8 | K12: P9 | L12: P10 (UTS)
C13: LISAN | D13: TULIS | E13: TUGAS | F13: PORT FL | G13: PG/ESAY | H13: KINERJA PRODUK | I13: KINERJA PRAKTIK | J13: PROYEK | K13: PORT.FL | L13: PG/ESAY
A14: 1
A16: 2
A18: 3
A20: 4 | O20: Keterangan :
A22: 5
A24: 6
A26: 7
A28: DST
A31: Keterangan :
A32: Penilaian Pengetahuan : | F32: Penilaian Ketrampilan :
A33: P1 : Penilaian Lisan | F33: P6 : Penilaian Kinerja (produk)
A34: P2 : Penilaian Tertulis | F34: P6 : Penilaian Kinerja (praktik)
A35: P3 : Penilaian Penugasan | F35: P8 : Penilaian Proyek
A36: P4 : Penilaian Portofolio | F36: P9 : Penilaian Portofolio
A37: P5 : Penilaian Harian
I39: Yogyakarta, Juli 2022
B40: Mengetahui :
B41: KP/Koordinator Mapel | I41: Pendidik,
B46: NIP. | I46: NIP.
B48: Kepala Sekolah | I48: WKS 1
B52: Drs. B Sabri | I52: Maryuli Darmawan, S.Pd. M.Eng
B53: NIP. 19630830 198703 1 003 | I53: NIP. 19700720 199802 1 003

Sheet Rekap Nil.Peng.(24)
Y1: F/751/WKS1/-/49
Y2: 43636
A3: REKAPITULASI PENILAIAN PENGETAHUAN
A4: Program Keahlian | C4: :
A5: Mata Pelajaran | C5: :
A6: Kelas | C6: :
A7: Semester | C7: :
A8: No | B8: Nama | D8: P1 | G8: P2 | J8: P3 | M8: P4 | P8: P5 ( UH) | S8: P10 (UTS) PG, Essay | V8: P11 | AA8: N KD
C9: KD | D9: Lisan | G9: Tulis | J9: Tugas | M9: Portfol | P9: PG, Essay | V9: UAS | Y9: ΣNA | Z9: ΣB | AB9: NR
D10: N | E10: B | F10: NA | G10: N | H10: B | I10: NA | J10: N | K10: B | L10: NA | M10: N | N10: B | O10: NA | P10: N | Q10: B | R10: NA | S10: N | T10: B | U10: NA | V10: N | W10: B | X10: NA
A11: 1 | B11: Aliansyah | C11: 0.12569444 | D11: 90 | E11: 2 | F11: 180 | G11: 80 | H11: 1 | I11: 80 | M11: 80 | N11: 3 | O11: 240 | Y11: 500 | Z11: 6 | AA11: 83 | AB11: 74
C12: 0.12638889 | D12: 70 | E12: 2 | F12: 140 | M12: 80 | N12: 3 | O12: 240 | Y12: 380 | Z12: 5 | AA12: 76
C13: 0.12708333 | G13: 70 | H13: 1 | I13: 70 | J13: 80 | K13: 2 | L13: 160 | M13: 80 | N13: 3 | O13: 240 | Y13: 470 | Z13: 6 | AA13: 78
C14: 0.12777778 | P14: 85 | Q14: 1 | R14: 85 | S14: 60 | T14: 2 | U14: 120 | V14: 60 | W14: 3 | X14: 180 | Y14: 385 | Z14: 6 | AA14: 64
C15: 0.12847222 | S15: 70 | T15: 2 | U15: 140 | V15: 70 | W15: 3 | X15: 210 | Y15: 350 | Z15: 5 | AA15: 70
A16: 2 | B16: Aminuddin | C16: 0.12569444 | D16: 80 | E16: 2 | F16: 160 | G16: 86 | H16: 1 | I16: 86 | M16: 80 | N16: 3 | O16: 240 | Y16: 486 | Z16: 6 | AA16: 81 | AB16: 80
C17: 0.12638889 | D17: 80 | E17: 2 | F17: 160 | M17: 80 | N17: 3 | O17: 240 | Y17: 400 | Z17: 5 | AA17: 80
C18: 0.12708333 | G18: 85 | H18: 1 | I18: 85 | J18: 80 | K18: 2 | L18: 160 | M18: 80 | N18: 3 | O18: 240 | Y18: 485 | Z18: 6 | AA18: 81
C19: 0.12777778 | P19: 85 | Q19: 1 | R19: 85 | S19: 85 | T19: 2 | U19: 170 | V19: 80 | W19: 3 | X19: 240 | Y19: 495 | Z19: 6 | AA19: 83
C20: 0.12847222 | S20: 70 | T20: 2 | U20: 140 | V20: 80 | W20: 3 | X20: 240 | Y20: 380 | Z20: 5 | AA20: 76
A21: 3 | B21: Budi Sulistyo | C21: 0.12569444 | D21: 90 | E21: 2 | F21: 180 | G21: 80 | H21: 1 | I21: 80 | M21: 80 | N21: 3 | O21: 240 | Y21: 500 | Z21: 6 | AA21: 83 | AB21: 82
C22: 0.12638889 | D22: 90 | E22: 2 | F22: 180 | M22: 80 | N22: 3 | O22: 240 | Y22: 420 | Z22: 5 | AA22: 84
C23: 0.12708333 | G23: 80 | H23: 1 | I23: 80 | J23: 75 | K23: 2 | L23: 150 | M23: 80 | N23: 3 | O23: 240 | Y23: 470 | Z23: 6 | AA23: 78
C24: 0.12777778 | P24: 85 | Q24: 1 | R24: 85 | S24: 80 | T24: 2 | U24: 160 | V24: 85 | W24: 3 | X24: 255 | Y24: 500 | Z24: 6 | AA24: 83
C25: 0.12847222 | S25: 80 | T25: 2 | U25: 160 | V25: 80 | W25: 3 | X25: 240 | Y25: 400 | Z25: 5 | AA25: 80
A26: dst
A28: Keterangan :
A29: N : Nilai | C29: NA : Jumlah N x A
A30: B : Bobot | C30: B : jumlah Bobot
A31: NA : N x B | C31: NKD : Jumlah N x A / Jumlah Bobot
C32: NR : Nilai Raport
S37: Yogyakarta, Juli 2019
A38: Mengetahui :
A39: KP/Koordinator Mapel | S39: Pendidik,
A44: NIP. | S44: NIP.
A46: Kepala Sekolah | S46: WKS 1
A50: Drs. B Sabri | S50: Maryuli Darmawan, S.Pd. M.Eng
A51: NIP. 19630830 198703 1 003 | S51: NIP. 19700720 199802 1 003

Sheet Rekap Nil. Ket (25)
Y1: F/751/WKS1/-/50
Y2: 43636
A3: REKAPITULASI PENILAIAN KETERAMPILAN
A4: Program Keahlian | C4: :
A5: Mata Pelajaran | C5: :
A6: Kelas | C6: :
A7: Semester | C7: :
A8: No | B8: Nama | C8: KD | D8: P6 | G8: P7 | J8: Nilai | M8: P8 | P8: Nilai | S8: P9 | V8: Nilai | AA8: N KD
D9: Kinerja (Produk) | G9: Kinerja (Praktik) | J9: Kinerja | M9: Proyek | P9: Proyek | S9: Portofolio | V9: Portofolio | Y9: ΣNA | Z9: ΣB | AB9: NR
D10: N | E10: B | F10: NA | G10: N | H10: B | I10: NA | J10: NO | K10: B | L10: NA | M10: N | N10: B | O10: NA | P10: NO | Q10: B | R10: NA | S10: N | T10: B | U10: NA | V10: NO | W10: B | X10: NA
A11: 1 | B11: Aliansyah | C11: 0.12569444 | D11: 80 | E11: 1 | F11: 80 | Y11: 80 | Z11: 1 | AA11: 80 | AB11: 82
C12: 0.12638889 | G12: 80 | H12: 1 | I12: 80 | Y12: 80 | Z12: 1 | AA12: 80
C13: 0.12708333 | J13: 80 | K13: 1 | L13: 80 | Y13: 80 | Z13: 1 | AA13: 80
C14: 0.12777778 | M14: 80 | N14: 2 | O14: 160 | P14: 80 | Q14: 2 | R14: 160 | Y14: 80 | Z14: 2 | AA14: 160
C15: 0.12847222 | S15: 90 | T15: 1 | U15: 90 | V15: 90 | W15: 1 | X15: 90 | Y15: 90 | Z15: 1 | AA15: 90
A16: 2 | B16: Aminuddin | C16: 0.12569444 | D16: 80 | E16: 1 | F16: 80 | Y16: 80 | Z16: 1 | AA16: 80 | AB16: 78
C17: 0.12638889 | G17: 80 | H17: 1 | I17: 80 | Y17: 80 | Z17: 1 | AA17: 80
C18: 0.12708333 | J18: 80 | K18: 1 | L18: 80 | Y18: 80 | Z18: 1 | AA18: 80
C19: 0.12777778 | M19: 80 | N19: 2 | O19: 160 | P19: 75 | Q19: 2 | R19: 150 | Y19: 75 | Z19: 2 | AA19: 150
C20: 0.12847222 | S20: 80 | T20: 1 | U20: 80 | V20: 80 | W20: 1 | X20: 80 | Y20: 80 | Z20: 1 | AA20: 80
A21: 3 | B21: Budi Sulistyo | C21: 0.12569444 | D21: 85 | E21: 1 | F21: 85 | Y21: 85 | Z21: 1 | AA21: 85 | AB21: 84
C22: 0.12638889 | G22: 80 | H22: 1 | I22: 80 | Y22: 80 | Z22: 1 | AA22: 80
C23: 0.12708333 | J23: 90 | K23: 1 | L23: 90 | Y23: 90 | Z23: 1 | AA23: 90
C24: 0.12777778 | M24: 80 | N24: 2 | O24: 160 | P24: 80 | Q24: 2 | R24: 160 | Y24: 80 | Z24: 2 | AA24: 160
C25: 0.12847222 | S25: 90 | T25: 1 | U25: 90 | V25: 90 | W25: 1 | X25: 90 | Y25: 90 | Z25: 1 | AA25: 90
A27: Keterangan :
A28: N : Nilai | C28: NA : Jumlah N x A
A29: B : Bobot | C29: B : jumlah Bobot
A30: NA : N x B | C30: NKD : Jumlah N x A / Jumlah Bobot
C31: NR : Nilai Raport
S36: Yogyakarta, Juli 2019
A37: Mengetahui :
A38: KP/Koordinator Mapel | S38: Pendidik,
A43: NIP. | S43: NIP.
A45: Kepala Sekolah | S45: WKS 1
A49: Drs. B Sabri | S49: Maryuli Darmawan, S.Pd. M.Eng
A50: NIP. 19630830 198703 1 003 | S50: NIP. 19700720 199802 1 003
B54: SEKOLAH MENENTUKAN KRITERIA PENILAIAN SIKAP
B55: NORMA AGAMA | C55: PACARAN
B56: NORMA SUSILA | C56: AGAMA

Sheet Telaah Soal PG (25)
G1: F/751/WKS1/-/25
G2: 45117
A4: INSTRUMEN TELAAH SOAL PILIHAN GANDA
A5: Sekolah | C5: :
A6: Paket Keahlian | C6: :
A7: Mata Pelajaran | C7: :
A8: Kelas | C8: :
A9: Semester | C9: :
A10: Elemen | C10: :
A11: NO | B11: ASPEK YANG DINILAI | C11: RESPON | D11: SKOR SOAL NO
A12: I | B12: MATERI | D12: 1 | E12: 2 | F12: 3 | G12: 4 | H12: 5 | I12: 6 | J12: dst
B13: 1. Soal sesuai indicator | C13: (1) soal sesuai indikator
C14: (0) soal tidak sesuai indicator
B15: 2. Soal dan pilihan jawaban tidak bersifat SARA, propaganda, pornografi, bermuatan politis, dan kekerasan | C15: (1) Soal dan pilihan jawaban tidak bersifat SARA, propaganda, pornografi, bermuatan politis, dan kekerasan
C16: (0) Soal dan pilihan jawaban bersifat SARA, propaganda, pornografi, bermuatan politis, dan kekerasan
B17: 3. Pilihan jawaban homogen dan logis | C17: (2) pilihan jawaban homogin dan logis
C18: (1)pilihan jawaban homogin atau logis
C19: (0) pilihan jawaban tidak homogin dan tidak logis
B20: 4. Hanya ada satu kunci jawaban | C20: (1) kunci jawaban hanya satu
C21: (0) kunci jawaban lebih dari satu atau tidak ada atau salah
A22: II | B22: KOMPETENSI
B23: 1. Pokok soal jelas dan tegas | C23: (2) Pokok soal jelas dan tegas
C24: (1) Pokok soal jelas atau tegas
C25: (0) Pokok soal tidak jelas dan tidak tegas
B26: 2. Pokok soal atau pilihan jawaban merupakan pernyataan yang diperlukan | C26: (1) Pokok soal atau pilihan jawaban merupakan pernyataan yang diperlukan
C27: (0) Pokok soal atau pilihan jawaban bukan merupakan pernyataan yang diperlukan
B28: 3. Pokok soal tidak member petunjuk ke arah jawaban yang benar | C28: (1) Pokok soal tidak member petunjuk ke arah jawaban yang benar
C29: (0) Pokok soal tidak member petunjuk ke arah jawaban yang benar
B30: 4. Pokok soal tidak mengandung pernyataan yang bersifat negatif ganda | C30: (1) Tidak mengandung pernyataan yang bersifat negatif ganda
C31: (0) Mengandung pernyataan yang bersifat negatif ganda
B32: 5. Panjang rumusan pilihan jawaban relative sama | C32: (1) Panjang rumusan pilihan jawaban relative sama
C33: (0) Salah satu rumusan pilihan jawaban panjang
B34: 6. Pilihan jawaban tidak mengandung pernyataan “semua pilihan jawaban di atas salah” atau “ semua pilihan jawaban di atas benar” | C34: (1) Pilihan jawaban tidak mengandung pernyataan “semua pilihan jawaban di atas salah” atau “ semua pilihan jawaban di atas benar”
C35: (0) Pilihan jawaban mengandung pernyataan “semua pilihan jawaban di atas salah” atau “ semua pilihan jawaban di atas benar”
B37: 7. Pilihan jawaban yang berbentuk angka atau waktu disusun berdasarkan urutan besar kecilnya nilai angka tersebut, atau kronologis | C37: (*) pilihan jawaban tidak berbentuk urutan angka atau urutan waktu
C38: (1) Pilihan jawaban yang berbentuk angka disusun berdasarkan urutan kecil ke besar atau sebaliknya dan pilihan jawaban waktu berdasarkan kronologisnya
C39: (0) Pilihan yang berbentuk angka tidak disusun berdasarkan urutan kecil ke besar atau sebaliknya dan pilihan jawaban waktu tidak berdasarkan kronologisnya
B40: 8. Gambar, grafik, table, diagram, dan sejenisnya yang terdapat pada soal jelas dan berfungsi | C40: (*) tidk terdapat gambar, grafik, table, diagram, dan sejenisnya
C41: (1) gambar, grafik, table, diagram, dan sejenisnya pada soal jelas dan berfungsi
C42: (0) gambar, grafik, table, diagram, dan sejenisnya pada soal jelas dan berfungsi
...

Sheet Telaah Soal Essay (26)
G1: F/751/WKS1/-/26
G2: 45117
A3: INSTRUMEN TELAAH SOAL URAIAN/ESSAY
A4: Sekolah | C4: :
A5: Paket Keahlian | C5: :
A6: Mata Pelajaran | C6: :
A7: Kelas | C7: :
A8: Semester | C8: :
A9: Elemen | C9: :
A10: NO | B10: ASPEK YANG DINILAI | C10: RESPON | D10: SKOR SOAL NO
A11: I | B11: MATERI | D11: 1 | E11: 2 | F11: 3 | G11: 4 | H11: 5 | I11: 6 | J11: dst
B12: 1. Soal sesuai dengan indikator (menuntut tes bentuk uraian) | C12: (1) soal sesuai indikator
C13: (0) soal tidak sesuai indicator
B14: 2. Batasan pertanyaan dan jawaban yang diharapkan sesuai | C14: (1) Soal dan pilihan jawaban tidak bersifat SARA, propaganda, pornografi, bermuatan politis, dan kekerasan
C15: (0) Soal dan pilihan jawaban bersifat SARA, propaganda, pornografi, bermuatan politis, dan kekerasan
B16: A. Materi yang diukur sesuai dengan kompetensi (UKRK) | C16: (2) pilihan jawaban homogin dan logis
C17: (1)pilihan jawaban homogin atau logis
C18: (0) pilihan jawaban tidak homogin dan tidak logis
B19: B. Isi materi yang ditanyakan sesuai dengan jenjang, jenis sekolah, dan tingkat kelas | C19: (1) kunci jawaban hanya satu
C20: (0) kunci jawaban lebih dari satu atau tidak ada atau salah
A21: II | B21: KOMPETENSI
B22: 1. Ada petunjuk yang jelas mengenai cara mengerjakan soal | C22: (1) Ada petunjuk yang jelas mengenai cara mengerjakan soal
C23: (0) Tidak ada petunjuk yang jelas mengenai cara mengerjakan soal
B24: 2. Rumusan kalimat Soal/ pertanyaan menggunakan kata tanya atau perintah yang menuntut jawaban terurai | C24: (1) Rumusan kalimat Soal/ pertanyaan menggunakan kata tanya atau perintah yang menuntut jawaban terurai
C25: (0) Rumusan kalimat Soal/ pertanyaan tidak menggunakan kata tanya atau perintah yang menuntut jawaban terurai
B26: 3. Gambar/grafik/tabel/diagram dan sejenisnya harus jelas dan berfungsi | C26: (1) Gambar/grafik/tabel/diagram dan sejenisnya harus jelas dan berfungsi
C27: (0) Gambar/grafik/tabel/diagram dan sejenisnya tidak jelas dan tidakberfungsi
B28: 4. Ada pedoman penskoran | C28: (1) Ada pedoman penskoran
C29: (0) Tidak ada pedoman penskoran
A30: III | B30: BAHASA
B31: 1. Rumusan kalimat soal/pertanyaan komunikatif | C31: (1) Rumusan kalimat soal/pertanyaan komunikatif
C32: (0) Rumusan kalimat soal/pertanyaan tidak komunikatif
B33: 2. Butir soal menggunakan bahasa Indonesia yang baku | C33: (*) khusus Mulok Bahasa Daerah/sejenisnya pilih opsi ini
C34: (1) Butir soal menggunakan bahasa Indonesia yang baku
C35: (0) Butir soal tidak menggunakan bahasa Indonesia yang baku
B36: 3. Tidak mengandung kata-kata/kalimat yang menimbulkan penafsiran ganda atau salah pengertian | C36: (1) Tidak mengandung kata-kata/kalimat yang menimbulkan penafsiran ganda atau salah pengertian
C37: (0) mengandung kata-kata/kalimat yang menimbulkan penafsiran ganda atau salah pengertian
B38: 4. Tidak mengandung kata yang menyinggung perasaan | C38: (1) Tidak mengandung kata yang menyinggung perasaan
C39: (0) menggunakan bahasa yang komunikatif Tidak mengandung kata yang menyinggung perasaan
B40: 5. Tidak menggunakan bahasa yang berlaku setempat/tabu | C40: (1) Tidak menggunakan bahasa yang berlaku setempat/tabu
...

Sheet Alokasi Waktu (28)
A1: PEMBAGIAN ALOKASI WAKTU PADA SILABUS / CAPAIAN PEMBELAJARAN
A5: Sekolah | C5: :
A6: Program Keahlian | C6: :
A7: Mata Pelajaran | C7: :
A8: Kelas | C8: :
A9: Semester | C9: :
A11: NO | B11: KD / CP | C11: ALOKASI WAKTU | G11: KETERANGAN
C12: SILABUS | D12: PEMBELAJARAN
D13: TM | E13: TUGAS | F13: PKL
A14: 1 | C14: 4 | D14: 2 | E14: 2 | F14: -
A15: 2
A16: 3
A17: 4
A18: 5
A19: 6
A20: 7
A21: 8
A22: 9
A23: 10
A24: 11
A25: 12
A26: 13
F31: Yogyakarta, Juli 2022
B32: Mengetahui :
B33: KP/Koordinator Mapel | F33: Pendidik,
B38: NIP. | F38: NIP.
B40: Kepala Sekolah | F40: WKS 1
B44: Drs. B Sabri | F44: Maryuli Darmawan, S.Pd. M.Eng
B45: NIP. 19630830 198703 1 003 | F45: NIP. 19700720 199802 1 003
