Workbook

Sheet COVER 
A5: BUKU
A6: ADMINISTRASI PENDIDIK
A7: PENYUSUNAN PROGRAM
B26: Program Keahlian | E26: : Teknik Mesin
B27: Konsentrasi Keahlian | E27: : Teknik Pemesinan
B28: Mata Pelajaran | E28: : Mata Pelajaran Pilihan (CAM)
B29: Fase | E29: : F
B30: Kelas | E30: : XI TM3
B31: Semester | E31: : Gasal
B32: Tahun Pelajaran | E32: : 2025/2026
B34: Nama Pendidik | E34: : | F34: Hermawan Rochmadi, S. Pd.
B35: N I P | E35: : | F35: 19920317 201903 1 009
A38: SMK NEGERI 3 YOGYAKARTA
A39: JL. R. W. MONGINSIDI NO. 2 YOGYAKARTA 55233
A40: Telp./Fax : (0274) 513503, e-mail : humas@smkn3jogja.sch.id

Sheet Visi,Misi,Tuj&KebjkMutu
A1: VISI, MISI, TUJUAN DAN KEBIJAKAN MUTU
A2: SMK NEGERI 3 YOGYAKARTA
A3: VISI :
B4: Menjadi Lembaga Pendidikan dan Pelatihan yang mampu menyiapkan tamatan berkarakter, kompeten, berbudaya dan berwawasan lingkungan.
A5: MISI :
A6: 1 | B6: Melaksanakan Pendidikan dan Pelatihan untuk menghasilkan tamatan yang beriman, bertaqwa, kompeten, dan mandiri.
A7: 2 | B7: Melaksanakan Pendidikan dan Pelatihan untuk menghasilkan tamatan unggul dalam iptek dan mampu berkompetisi pada era globalisasi.
A8: 3 | B8: Melaksanakan Pendidikan dan Pelatihan yang berkualitas dengan standar Nasional.
A9: 4 | B9: Melaksanakan Pendidikan dan Pelatihan dengan menumbuhkan dan melestarikan budaya lokal.
A10: 5 | B10: Melaksanakan Pendidikan dan Pelatihan dengan membiasakan Warga Sekolah agar selalu peduli terhadap lingkungan.
A12: TUJUAN :
A14: 1 | B14: Menghasilkan tamatan yang beriman, bertaqwa, kompeten dan mandiri.
A15: 2 | B15: Menghasilkan tamatan yang unggul dalam iptek, mampu berkompetisi pada era globalisasi tanpa meninggalkan kearifan lokal.
A16: 3 | B16: Menjadi Lembaga Pendidikan dan Pelatihan yang berkualitas dengan standar Nasional.
A17: 4 | B17: Menampilkan sarana dan prasarana sekolah dengan wujud budaya jogja.
A18: 5 | B18: Menampilkan sikap sopan, santun dan budi pekerti sebagai cermin akhlak mulia tanpa meninggalkan budaya jogja.
A19: 6 | B19: Mengembangkan lingkungan sekolah menjadi sekolah adiwiyata dengan melibatkan warga sekolah, stake holder dan instansi terkait.
A21: KEBIJAKAN MUTU :
A23: H | B23: umanis | D23: KON | E23: struktif
A24: A | B24: gamis | D24: S | E24: istematis
A25: N | B25: ormatif | D25: I | E25: nteraktif
A26: D | B26: inamis | D26: S | E26: olutif
A27: A | B27: daptif | D27: T | E27: aktis
A28: L | B28: oyal | D28: E | E28: fektif-Efisien
D29: N | E29: yaman

Sheet Daftar Isi 
A2: DAFTAR ISI
A4: 1 | B4: Kalender pendidikan
A5: 2 | B5: Jadwal pelajaran
A6: 3 | B6: Perhitungan minggu efektif
A7: 4 | B7: Program tahunan
A8: 5 | B8: Program semester
A9: 6 | B9: Analisis CP
A10: 7 | B10: Analisa Materi
A11: 8 | B11: ATP
A12: 9 | B12: TP
A13: 10 | B13: KKTP
A14: 11 | B14: MA-LKPD
A15: 12 | B15: Daftar Hadir
... A29: 26 | B29: Telaah Soal Essay

Sheet kaldik (1)
A1: LAMPIRAN KALENDER PENDIDIKAN TAHUN AJARAN 2025/2026
A2: SMK N 3 Yogyakarta
A3: JULI 2025
A4: AHAD | C4: 6 | D4: 13 | E4: 20 | F4: 27 | I4: 1 - 11 Juli 2025 : Libur Akhir Tahun Ajaran 2024/2025
A5: SENIN | C5: 7 | D5: 14 | E5: 21 | F5: 28 | I5: 14 Juli 2025 : Hari Pertama Masuk Sekolah Tahun Ajaran Baru 2025/2026
A6: SELASA | B6: 1 | C6: 8 | D6: 15 | E6: 22 | F6: 29 | I6: 14 - 18 Juli 2025 : MPLS Tahun Ajaran Baru 2025/2026
A7: RABU | B7: 2 | C7: 9 | D7: 16 | E7: 23 | F7: 30 | I7: 31 Juli 2025 : Gelar Budaya SMK N 3 Yogyakarta
A8: KAMIS | B8: 3 | C8: 10 | D8: 17 | E8: 24 | F8: 31 | I8: Minggu Efektif | K8: : | L8: 3 | R8: =L8 -> 3
A9: JUMÁT | B9: 4 | C9: 11 | D9: 18 | E9: 25 | I9: Hari Efektif | K9: : | L9: 9
A10: SABTU | B10: 5 | C10: 12 | D10: 19 | E10: 26
A12: AGUSTUS 2025
A13: AHAD | C13: 3 | D13: 10 | E13: 17 | F13: 24 | G13: 31 | I13: 4-7 Agustus 2025 : Pelaksanaan Asesmen Nasional
A14: SENIN | C14: 4 | D14: 11 | E14: 18 | F14: 25 | I14: 14 Agustur 2025 : SMK N 3 Bersolawat
A15: SELASA | C15: 5 | D15: 12 | E15: 19 | F15: 26 | I15: 17 Agustus 2025 : Proklamasi Kemerdekaan
A16: RABU | C16: 6 | D16: 13 | E16: 20 | F16: 27
A17: KAMIS | C17: 7 | D17: 14 | E17: 21 | F17: 28 | I17: Minggu Efektif | K17: : | L17: 4 | R17: =L17 -> 4
A18: JUMÁT | B18: 1 | C18: 8 | D18: 15 | E18: 22 | F18: 29 | I18: Hari Efektif | K18: : | L18: 21
A19: SABTU | B19: 2 | C19: 9 | D19: 16 | E19: 23 | F19: 30
A21: SEPTEMBER 2025
A22: AHAD | C22: 7 | D22: 14 | E22: 21 | F22: 28 | I22: 5 September 2025 : Maulid Nabi Muhammad SAW
A23: SENIN | B23: 1 | C23: 8 | D23: 15 | E23: 22 | F23: 29 | I23: 15 September 2025 : Pergantian Blok 2
A24: SELASA | B24: 2 | C24: 9 | D24: 16 | E24: 23 | F24: 30
A25: RABU | B25: 3 | C25: 10 | D25: 17 | E25: 24
A26: KAMIS | B26: 4 | C26: 11 | D26: 18 | E26: 25 | I26: Minggu Efektif | K26: : | L26: 4 | R26: =L26 -> 4
A27: JUMÁT | B27: 5 | C27: 12 | D27: 19 | E27: 26 | I27: Hari Efektif | K27: : | L27: 20
A28: SABTU | B28: 6 | C28: 13 | D28: 20 | E28: 27
A30: OKTOBER 2025
A31: AHAD | C31: 5 | D31: 12 | E31: 19 | F31: 26
A32: SENIN | C32: 6 | D32: 13 | E32: 20 | F32: 27
A33: SELASA | C33: 7 | D33: 14 | E33: 21 | F33: 28
A34: RABU | B34: 1 | C34: 8 | D34: 15 | E34: 22 | F34: 29
A35: KAMIS | B35: 2 | C35: 9 | D35: 16 | E35: 23 | F35: 30 | I35: Minggu Efektif | K35: : | L35: 5 | R35: =L35 -> 5
A36: JUMÁT | B36: 3 | C36: 10 | D36: 17 | E36: 24 | F36: 31 | I36: Hari Efektif | K36: : | L36: 25
A37: SABTU | B37: 4 | C37: 11 | D37: 18 | E37: 25
A39: 45962
A40: AHAD | C40: 2 | D40: 9 | E40: 16 | F40: 23 | G40: 30 | I40: 1-9 November 2025 : Tes Kemampuan Akademik
A41: SENIN | C41: 3 | D41: 10 | E41: 17 | F41: 24 | I41: 10-21 November 2025 : Ujian Kompetensi Keahlian Kelas XII (Gelombang 1)
A42: SELASA | C42: 4 | D42: 11 | E42: 18 | F42: 25 | I42: 25 November 2025 : Hari Guru Nasional
A43: RABU | C43: 5 | D43: 12 | E43: 19 | F43: 26 | I43: 26-28 November 2025 : Ujian Sekolah Kelas XII (Gelombang 1)
A44: KAMIS | C44: 6 | D44: 13 | E44: 20 | F44: 27 | I44: Minggu Efektif | K44: : | L44: 3 | R44: =L44 -> 3
...

Sheet Jadwal (2)
A1: JADWAL MENGAJAR SMK NEGERI 3 YOGYAKARTA | R1: F/751/WKS1/-/02
A2: Tahun Pelajaran 2025/2026 | R2: 45483
A4: HARI | B4: JAM KE | C4: 1 | D4: 2 | E4: 3 | F4: 4 | G4: 5 | H4: 6 | I4: 7 | J4: 8 | K4: 9 | L4: 10 | M4: 11 | N4: 12 | P4: Keterangan :
A6: SENIN | B6: Mata Pelajaran
B7: Kelas/Ruang
A8: SELASA | B8: Mata Pelajaran | C8: DDK
B9: Kelas/Ruang | C9: X TM1/2 - R72
A10: RABU | B10: Mata Pelajaran | C10: MPPTM
B11: Kelas/Ruang | C11: 11 TM3/4 - Lab Mastercam
A12: KAMIS | B12: Mata Pelajaran
B13: Kelas/Ruang
A14: JUM'AT | B14: Mata Pelajaran | C14: MPPTM
B15: Kelas/Ruang | C15: 11 TM1/2 - Lab Mastercam
B17: WAKTU PELAJARAN | K17: Catatan :
B18: Senin s.d Kamis | C18: Senin s.d Kamis | F18: Jumat | K18: Jumlah jam mengajar 24 jam
B19: Tidak Upacara | C19: Upacara : 07.00 - 08.00 | K19: Tugas Tambahan :
B20: LITERASI | C20: LITERASI | F20: GER TIMUN MAS | K20: 1. Wali Kelas X TM4 2 jam
B21: 0. 06.45 - 07.00 | C21: 0. 06.45 - 07.00 | F21: 0. 06.45 - 07.15
B22: 1. 07.00 - 07.45 | C22: 1. 08.00 - 08.40 | F22: 1. 07.15 - 07.55
B23: 2. 07.45 - 08.30 | C23: 2. 08.40 - 09.20 | F23: 2. 07.55 -08.35
B24: 3. 08.30 - 09.15 | C24: 3. 09.20 - 10.00 | F24: 3. 08.35 - 09.15
B25: 4. 09.15 - 10.00 | C25: 4. 10.00 - 10.40 | F25: 4. 09.15 - 09.55
B26: ISTIRAHAT ( 15' ) | C26: ISTIRAHAT ( 15' ) | F26: ISTIRAHAT ( 15' )
B27: 5. 10.15 - 11.00 | C27: 5. 11.05 - 11.45 | F27: 5. 10.10 - 10.50
B28: 6. 11.00 - 11.45 | C28: 6. 11.45 - 12.25 | F28: 6. 10.50 - 11.30
B29: ISTIRAHAT ( 30' ) | C29: ISTIRAHAT (20' ) | F29: SHOLAT JUMAT
B30: 7. 12.15 - 13.00 | C30: 7. 12.45 - 13.20 | F30: 7. 12.30 - 13.10
B31: 8. 13.00 - 13.45 | C31: 8. 13.20- 13.55 | F31: 8. 13.10 - 13.50
B32: 9. 13.45 - 14.30 | C32: 9. 13.55 - 14.30 | F32: 9. 13.50 - 14.30
... B36: 12. 16.15 - 17.00 | C36: 12. 16.05 - 16.40 | F36: 12. 16.10 - 16.50

Sheet Prhtngn Mingg Ef(3)
A1: PERHITUNGAN MINGGU EFEKTIF DAN JAM EFEKTIF | H1: F/751/WKS1/-/03
H2: 45483
A3: Program Keahlian | C3: ='COVER '!E26 -> : Teknik Mesin
A4: Konsentrasi Keahlian | C4: ='COVER '!E27 -> : Teknik Pemesinan
A5: Mata Pelajaran | C5: ='COVER '!E28 -> : Mata Pelajaran Pilihan (CAM)
A6: Fase | C6: ='COVER '!E29 -> : F
A7: Kelas | C7: ='COVER '!E30 -> : XI TM3
A8: Semester | C8: ='COVER '!E31 -> : Gasal
A9: Tahun Pelajaran | C9: ='COVER '!E32 -> : 2025/2026
A11: No. | B11: Bulan | C11: Jml Minggu dalam Semester | D11: Jml Minggu Tidak Efektif | F11: Jml Minggu Efektif | G11: Jml Hari Efektif | H11: Jml Jam Efektif
A12: 1 | B12: Juli | C12: 5 | D12: 2 | F12: =C12-D12 -> 3 | G12: =F12 -> 3 | H12: =G12*$E$20 -> 24
A13: 2 | B13: Agustus | C13: 4 | D13: 0 | F13: =C13-D13 -> 4 | G13: =F13 -> 4 | H13: =G13*$E$20 -> 32
A14: 3 | B14: September | C14: 4 | D14: 2 | F14: =C14-D14 -> 2 | G14: =F14 -> 2 | H14: =G14*$E$20 -> 16
A15: 4 | B15: Oktober | C15: 4 | D15: 4 | F15: =C15-D15 -> 0 | G15: =F15 -> 0 | H15: =G15*$E$20 -> 0
A16: 5 | B16: November | C16: 4 | D16: 4 | F16: =C16-D16 -> 0 | G16: =F16 -> 0 | H16: =G16*$E$20 -> 0
A17: 6 | B17: Desember | C17: 5 | D17: 5 | F17: =C17-D17 -> 0 | G17: =F17 -> 0 | H17: =G17*$E$20 -> 0
A18: Jumlah | C18: =SUM(C12:C17) -> 26 | D18: =SUM(D12:E17) -> 17 | F18: =SUM(F12:F17) -> 9 | G18: =SUM(G12:G17) -> 9 | H18: =SUM(H12:H17) -> 72
B20: Jumlah Jam Pelajaran per Minggu | D20: : | E20: 8 | F20: JP
B21: Jumlah Jam Pelajaran Efektif | D21: : | E21: =H18 -> 72 | F21: JP
B22: Rincian :
B23: a. Tatap Muka | D23: : | E23: =E27-E24-E25 -> 56 | F23: JP
B24: b. UH ( 3 x 4) | D24: : | E24: 12 | F24: JP
B25: c. Ulangan Tengah Semester | D25: : | E25: 4 | F25: JP | Q25: =SUM(Q17:Q24) -> 0
C27: Jumlah | D27: : | E27: =E21 -> 72 | F27: JP
F31: Yogyakarta, Juli 2025
B33: KPK Teknik Mesin | F33: Pendidik,
B37: Drs. M. Hasannuddin | F37: ='COVER '!F34 -> Hermawan Rochmadi, S. Pd.
B38: NIP. 19670621 199412 1 003 | F38: NIP. 19920317 201903 1 009
C40: Mengetahui :
B41: Kepala Sekolah | F41: WKS-1
B45: WIDADA, S.Pd., M.Pd. | F45: GUNAWAN, S.Pd., M.M.
B46: NIP. 19690212 200012 1 002 | F46: NIP. 19711213 200501 1 004
A52: PERHITUNGAN MINGGU EFEKTIF DAN JAM EFEKTIF | H52: F/751/WKS1/-/27
H53: 45117
A54: Program Keahlian | C54: ='COVER '!E26 -> : Teknik Mesin
A55: Konsentrasi Keahlian | C55: ='COVER '!E27 -> : Teknik Pemesinan
A56: Mata Pelajaran | C56: ='COVER '!E28 -> : Mata Pelajaran Pilihan (CAM)
A57: Fase | C57: ='COVER '!E29 -> : F
A58: Kelas | C58: ='COVER '!E30 -> : XI TM3
A59: Semester | C59: : Genap
...

Sheet PROTA (4)
E1: F/751/WKS1/-/04
E2: 45483
A3: PROGRAM TAHUNAN
B4: Program Keahlian | C4: ='COVER '!E26 -> : Teknik Mesin
B5: Konsentrasi Keahlian | C5: ='COVER '!E27 -> : Teknik Pemesinan
B6: Mata Pelajaran | C6: ='COVER '!E28 -> : Mata Pelajaran Pilihan (CAM)
B7: Fase | C7: ='COVER '!E29 -> : F
B8: Kelas | C8: ='COVER '!E30 -> : XI TM3
B9: Semester | C9: ='COVER '!E31 -> : Gasal
B10: Tahun Pelajaran | C10: ='COVER '!E32 -> : 2025/2026
B12: Semester | C12: Elemen/Topik Pembelajaran | D12: Alokasi Waktu ( JP ) | F12: Jumlah Jam
D13: Kegiatan Tatap Muka | E13: Evaluasi Tiap Kompetensi
B15: 3 | C15: 2D Modelling dengan software CAM | D15: 32 | E15: 8 | F15: =SUM(D15:E15) -> 40
C16: 3D Modelling dengan software CAM | D16: 28 | E16: 4 | F16: =SUM(D16:E16) -> 32
B17: 4 | C17: Pemrograman 2D dengan software CAM | D17: 32 | E17: 8 | F17: =SUM(D17:E17) -> 40
C18: Pemrograman 3D dengan software CAM | D18: 28 | E18: 4 | F18: =SUM(D18:E18) -> 32
B19: JUMLAH | D19: =SUM(D15:D18) -> 120 | E19: =SUM(E15:E18) -> 24 | F19: =SUM(D19:E19) -> 144
E24: Yogyakarta, Juli 2025
B25: ='Prhtngn Mingg Ef(3)'!B83 -> KPK Teknik Mesin | E25: Pendidik,
B29: ='Prhtngn Mingg Ef(3)'!B87 -> Drs. M. Hasannuddin | E29: ='Prhtngn Mingg Ef(3)'!G87 -> Hermawan Rochmadi, S. Pd.
B30: ='Prhtngn Mingg Ef(3)'!B88 -> NIP. 19670621 199412 1 003 | E30: ='Prhtngn Mingg Ef(3)'!G88 -> NIP. 19920317 201903 1 009
C32: ='Prhtngn Mingg Ef(3)'!C90:E90 -> Mengetahui
B33: ='Prhtngn Mingg Ef(3)'!B91 -> Kepala Sekolah | E33: ='Prhtngn Mingg Ef(3)'!G91 -> WKS-1
B37: ='Prhtngn Mingg Ef(3)'!B95 -> WIDADA, S.Pd., M.Pd. | E37: ='Prhtngn Mingg Ef(3)'!G95 -> GUNAWAN, S.Pd., M.M.
B38: ='Prhtngn Mingg Ef(3)'!B96 -> NIP. 19690212 200012 1 002 | E38: ='Prhtngn Mingg Ef(3)'!G96 -> NIP. 19711213 200501 1 004

Sheet PROSEM(5)  
Y1: F/751/WKS1/-/05
Y2: 45483
A3: PROGRAM SEMESTER
B5: Program Keahlian | C5: ='COVER '!E26 -> : Teknik Mesin
B6: Konsentrasi Keahlian | C6: ='COVER '!E27 -> : Teknik Pemesinan
B7: Mata Pelajaran | C7: ='COVER '!E28 -> : Mata Pelajaran Pilihan (CAM)
B8: Fase | C8: ='COVER '!E29 -> : F
B9: Kelas | C9: ='COVER '!E30 -> : XI TM3
B10: Semester | C10: ='COVER '!E31 -> : Gasal
B11: Tahun Pelajaran | C11: ='COVER '!E32 -> : 2025/2026
A13: No | B13: Elemen/Topik Pembelajaran | C13: Jml Jam | D13: Bulan | AD13: Ket.
D14: Juli | I14: Agustus | M14: Septermber | Q14: Oktober | U14: November | Z14: Desember
D15: 1 | E15: 2 | F15: 3 | G15: 4 | H15: 5 | I15: 1 | J15: 2 | K15: 3 | L15: 4 | M15: 1 | N15: 2 | O15: 3 | P15: 4 | Q15: 1 | R15: 2 | S15: 3 | T15: 4 | U15: 1 | V15: 2 | W15: 3 | X15: 4 | Y15: 5 | Z15: 1 | AA15: 2 | AB15: 3 | AC15: 4
A16: 1 | B16: ='PROTA (4)'!C15 -> 2D Modelling dengan software CAM | C16: 40
A17: 2 | B17: ='PROTA (4)'!C16 -> 3D Modelling dengan software CAM | C17: 32
B19: Mengetahui : | C19: WKS-1 | O19: KPK Teknik Mesin | Y19: Pendidik,
B20: Kepala Sekolah
B23: ='PROTA (4)'!B37 -> WIDADA, S.Pd., M.Pd. | C23: ='PROTA (4)'!E37 -> GUNAWAN, S.Pd., M.M. | O23: ='PROTA (4)'!B29 -> Drs. M. Hasannuddin | Y23: ='PROTA (4)'!E29 -> Hermawan Rochmadi, S. Pd.
B24: ='PROTA (4)'!B38 -> NIP. 19690212 200012 1 002 | C24: ='PROTA (4)'!E38 -> NIP. 19711213 200501 1 004 | O24: ='PROTA (4)'!B30 -> NIP. 19670621 199412 1 003 | Y24: ='PROTA (4)'!E30 -> NIP. 19920317 201903 1 009
A27: PROGRAM SEMESTER
B29: Program Keahlian | C29: ='COVER '!E26 -> : Teknik Mesin
B30: Konsentrasi Keahlian | C30: ='COVER '!E27 -> : Teknik Pemesinan
B31: Mata Pelajaran | C31: ='COVER '!E28 -> : Mata Pelajaran Pilihan (CAM)
B32: Fase | C32: ='COVER '!E29 -> : F
B33: Kelas | C33: ='COVER '!E30 -> : XI TM3
B34: Semester | C34: ='Prhtngn Mingg Ef(3)'!C59 -> : Genap
B35: Tahun Pelajaran | C35: ='COVER '!E32 -> : 2025/2026
A37: No | B37: Elemen/Topik Pembelajaran | C37: Jml Jam | D37: Bulan | AC37: Ket.
D38: Januari | H38: Februari | L38: Maret | P38: April | U38: Mei | Y38: Juni
D39: 1 | E39: 2 | F39: 3 | G39: 4 | H39: 1 | I39: 2 | J39: 3 | K39: 4 | L39: 1 | M39: 2 | N39: 3 | O39: 4 | P39: 1 | Q39: 2 | R39: 3 | S39: 4 | T39: 5 | U39: 1 | V39: 2 | W39: 3 | X39: 4 | Y39: 1 | Z39: 2 | AA39: 3 | AB39: 4
A40: 1 | B40: ='PROTA (4)'!C17 -> Pemrograman 2D dengan software CAM | C40: 40
A41: 2 | B41: ='PROTA (4)'!C18 -> Pemrograman 3D dengan software CAM | C41: 32 | J41: ** | AC41: ** = Libur awal ramadhan
B45: Mengetahui :
B46: Kepala Sekolah | C46: WKS-1 | O46: ='PROTA (4)'!B25 -> KPK Teknik Mesin | Y46: Pendidik,
B49: =B23 -> WIDADA, S.Pd., M.Pd. | C49: =C23 -> GUNAWAN, S.Pd., M.M. | O49: =O23 -> Drs. M. Hasannuddin | Y49: =Y23 -> Hermawan Rochmadi, S. Pd.
B50: =B24 -> NIP. 19690212 200012 1 002 | C50: =C24 -> NIP. 19711213 200501 1 004 | O50: =O24 -> NIP. 19670621 199412 1 003 | Y50: =Y24 -> NIP. 19920317 201903 1 009

Sheet CP (6)
D1: F/751/WKS1/-/06
D2: 45483
A3: ANALISIS CAPAIAN PEMBELAJARAN
A5: Program Keahlian | C5: ='COVER '!E26 -> : Teknik Mesin
A6: Konsentrasi Keahlian | C6: ='COVER '!E27 -> : Teknik Pemesinan
A7: Mata Pelajaran | C7: ='COVER '!E28 -> : Mata Pelajaran Pilihan (CAM)
A8: Fase | C8: ='COVER '!E29 -> : F
A9: Kelas | C9: ='COVER '!E30 -> : XI TM3
A10: Semester | C10: ='COVER '!E31 -> : Gasal
A11: Tahun Pelajaran | C11: : 2025/2026
A13: NO | B13: ELEMEN | C13: CAPAIAN PEMBELAJARAN
A14: 1 | B14: Mata Pelajaran Pilihan Pemesinan (CAM) | C14: Pada fase ini, peserta didik mampu mendemonstrasikan pembuatan modelling 2D dan 3D serta pemrograman 2D dan 3D menggunakan software CAM
D16: Yogyakarta, Juli 2025
A17: ='PROSEM(5) '!O46 -> KPK Teknik Mesin | D17: Pendidik,
A21: ='PROTA (4)'!B29 -> Drs. M. Hasannuddin | D21: ='PROTA (4)'!E29 -> Hermawan Rochmadi, S. Pd.
A22: ='PROTA (4)'!B30 -> NIP. 19670621 199412 1 003 | D22: ='PROTA (4)'!E30 -> NIP. 19920317 201903 1 009
A24: ='PROSEM(5) '!B46 -> Kepala Sekolah | D24: ='PROSEM(5) '!C46 -> WKS-1
A28: ='PROSEM(5) '!B49 -> WIDADA, S.Pd., M.Pd. | D28: ='PROSEM(5) '!C49 -> GUNAWAN, S.Pd., M.M.
A29: ='PROSEM(5) '!B50 -> NIP. 19690212 200012 1 002 | D29: ='PROSEM(5) '!C50 -> NIP. 19711213 200501 1 004

Sheet Analisis Materi (7)
F1: F/751/WKS1/-/07
F2: 45483
A3: ANALISIS MATERI PEMBELAJARAN
A5: Program Keahlian | C5: ='COVER '!E26 -> : Teknik Mesin
A6: Konsentrasi Keahlian | C6: ='COVER '!E27 -> : Teknik Pemesinan
A7: Mata Pelajaran | C7: ='COVER '!E28 -> : Mata Pelajaran Pilihan (CAM)
A8: Fase | C8: ='COVER '!E29 -> : F
A9: Kelas | C9: ='COVER '!E30 -> : XI TM3
A10: Semester | C10: ='COVER '!E31 -> : Gasal
A11: Tahun Pelajaran | C11: ='COVER '!E32 -> : 2025/2026
A13: No. | B13: Elemen/Topik Pembelajaran | C13: Kode Profil | D13: Jumlah Jam | E13: Tempat Pembelajaran
E14: Sekolah (Jam.pel) | F14: DU/DI (Jam.pel)
A15: 1 | B15: ='PROTA (4)'!C15 -> 2D Modelling dengan software CAM | C15: SEM 3 | D15: ='PROTA (4)'!F15 -> 40 | E15: =D15 -> 40 | F15: 0
A16: 2 | B16: ='PROTA (4)'!C16 -> 3D Modelling dengan software CAM | C16: SEM 3 | D16: ='PROTA (4)'!F16 -> 32 | E16: =D16 -> 32 | F16: 0
A17: 3 | B17: ='PROTA (4)'!C17 -> Pemrograman 2D dengan software CAM | C17: SEM 4 | D17: ='PROTA (4)'!F17 -> 40 | E17: =D17 -> 40 | F17: 0
A18: 4 | B18: ='PROTA (4)'!C18 -> Pemrograman 3D dengan software CAM | C18: SEM4 | D18: ='PROTA (4)'!F18 -> 32 | E18: =D18 -> 32 | F18: 0
D20: Yogyakarta, Juli 2025
B22: ='CP (6)'!A17 -> KPK Teknik Mesin | D22: Pendidik,
B26: ='CP (6)'!A21 -> Drs. M. Hasannuddin | D26: ='CP (6)'!D21 -> Hermawan Rochmadi, S. Pd.
B27: ='CP (6)'!A22 -> NIP. 19670621 199412 1 003 | D27: ='CP (6)'!D22 -> NIP. 19920317 201903 1 009
B28: Mengetahui
B29: ='CP (6)'!A24 -> Kepala Sekolah | D29: ='CP (6)'!D24 -> WKS-1
B33: ='CP (6)'!A28 -> WIDADA, S.Pd., M.Pd. | D33: ='CP (6)'!D28 -> GUNAWAN, S.Pd., M.M.
B34: ='CP (6)'!A29 -> NIP. 19690212 200012 1 002 | D34: ='CP (6)'!D29 -> NIP. 19711213 200501 1 004

Sheet ATP (8)
E2: F/751/WKS1/-/08
E3: 45483
A4: ALUR TUJUAN PEMBELAJARAN
A6: Program Keahlian | C6: ='COVER '!E26 -> : Teknik Mesin
A7: Konsentrasi Keahlian | C7: ='COVER '!E27 -> : Teknik Pemesinan
A8: Mata Pelajaran | C8: ='COVER '!E28 -> : Mata Pelajaran Pilihan (CAM)
A9: Fase | C9: ='COVER '!E29 -> : F
A10: Kelas | C10: ='COVER '!E30 -> : XI TM3
A11: Semester | C11: ='COVER '!E31 -> : Gasal
A12: Tahun Pelajaran | C12: ='COVER '!E32 -> : 2025/2026
A14: Alur No | B14: Elemen CP | C14: Topik Pelajaran | D14: Kode | E14: Alokasi Waktu | F14: Semester
A15: 1 | B15: ='Analisis Materi (7)'!B15 -> 2D Modelling dengan software CAM | C15: 2D modelling dengan CAM | D15: MPP1 | E15: ='Analisis Materi (7)'!E15 -> 40 | F15: 3
A16: 2 | B16: 3D Modelling dengan software CAM | C16: 3D modelling dengan CAM | D16: MPP2 | E16: ='Analisis Materi (7)'!E16 -> 32 | F16: 3
A17: 3 | B17: ='Analisis Materi (7)'!B17 -> Pemrograman 2D dengan software CAM | C17: Pemrograman contour, drill, dan pocket 2D | D17: MPP3 | E17: ='Analisis Materi (7)'!E17 -> 40 | F17: 4
A18: 4 | B18: ='Analisis Materi (7)'!B18 -> Pemrograman 3D dengan software CAM | C18: Pemrograman 3D | D18: MPP4 | E18: ='Analisis Materi (7)'!E18 -> 32 | F18: 4
A19: JUMLAH | E19: =SUM(E15:E18) -> 144
D21: Yogyakarta, Juli 2025
B23: ='Analisis Materi (7)'!B22 -> KPK Teknik Mesin | D23: Pendidik,
B27: ='Analisis Materi (7)'!B26 -> Drs. M. Hasannuddin | D27: ='Analisis Materi (7)'!D26 -> Hermawan Rochmadi, S. Pd.
B28: ='Analisis Materi (7)'!B27 -> NIP. 19670621 199412 1 003 | D28: ='Analisis Materi (7)'!D27 -> NIP. 19920317 201903 1 009
B29: ='Analisis Materi (7)'!B28 -> Mengetahui
B30: ='Analisis Materi (7)'!B29 -> Kepala Sekolah | D30: ='Analisis Materi (7)'!D29 -> WKS-1
B34: ='Analisis Materi (7)'!B33 -> WIDADA, S.Pd., M.Pd. | D34: ='Analisis Materi (7)'!D33 -> GUNAWAN, S.Pd., M.M.
B35: ='Analisis Materi (7)'!B34 -> NIP. 19690212 200012 1 002 | D35: ='Analisis Materi (7)'!D34 -> NIP. 19711213 200501 1 004

Sheet TP (9)
B1: TUJUAN PEMBELAJARAN
C2: Program Keahlian | D2: ='COVER '!E26 -> : Teknik Mesin | J2: F/751/WKS1/-/09
C3: Konsentrasi Keahlian | D3: ='COVER '!E27 -> : Teknik Pemesinan | J3: 45483
C4: Mata Pelajaran | D4: ='COVER '!E28 -> : Mata Pelajaran Pilihan (CAM)
C5: Fase | D5: ='COVER '!E29 -> : F
C6: Kelas | D6: ='COVER '!E30 -> : XI TM3
C7: Semester | D7: ='COVER '!E31 -> : Gasal
C8: Tahun Pelajaran | D8: ='COVER '!E32 -> : 2025/2026
B10: Alur No | C10: Tujuan Pembelajaran | D10: Kelas/ Semester | E10: Topik Pelajaran | F10: Pemahaman Bermakna | G10: Rencana Asesmen | H10: Model Pembelajaran | I10: Alokasi Waktu | J10: Sumber Belajar | K10: Ket.
B11: 1 | C11: Memahami teknik pemesinan bubut meliputi teknik pembubutan benda sederhana serta kompeten sebagai operator mesin bubut dalam mengerjakan job TEFA | D11: XII TM1 / 5 | E11: Membubut Ulir | F11: Siswa mampu mengidentifikasi dan memecahkan masalah yang timbul dalam proses pemesinan bubut lanjutan secara mandiri maupun kolaboratif, serta memberikan solusi perbaikan untuk meningkatkan efisiensi dan kualitas produksi. | G11: Proyek | H11: Praktik | I11: 20 | J11: Manual Book
J13: Yogyakarta, Juli 2025
C14: Mengetahui :
C15: Kepala Sekolah | E15: WKS 1 | G15: ='ATP (8)'!B23 -> KPK Teknik Mesin | J15: Pendidik,
C19: ='PROSEM(5) '!B49 -> WIDADA, S.Pd., M.Pd. | E19: ='PROSEM(5) '!C49 -> GUNAWAN, S.Pd., M.M. | G19: ='PROSEM(5) '!O49 -> Drs. M. Hasannuddin | J19: ='PROSEM(5) '!Y49 -> Hermawan Rochmadi, S. Pd.
C20: ='PROSEM(5) '!B50 -> NIP. 19690212 200012 1 002 | E20: ='PROSEM(5) '!C50 -> NIP. 19711213 200501 1 004 | G20: ='PROSEM(5) '!O50 -> NIP. 19670621 199412 1 003 | J20: ='PROSEM(5) '!Y50 -> NIP. 19920317 201903 1 009

Sheet KKTP (10)
D1: F/751/WKS1/-/10
D2: 45117 | H2: LEMBAR TERSENDIRI
B5: ANALISA PENGHITUNGAN KKTP | G5: NO | H5: Tujuan Pembelajaran | I5: Indikator Ketercapaian KKTP | J5: Level KKTP | N5: Tindak Lanjut
B6: KRITERIA KETERCAPAIAN TUJUAN PEMBELAJARAN | J6: Baru Berkembang | K6: Layak | L6: Cakap | M6: Mahir
G7: 1 | H7: Memahami teknik pemesinan bubut meliputi teknik pembubutan benda sederhana serta kompeten sebagai operator mesin bubut dalam mengerjakan job TEFA | I7: Kompeten sebagai operator mesin bubut dalam mengerjakan job TEFA. | J7: 0 – 40% | K7: 41 – 74 % | L7: 75 – 85% | M7: 86 – 100% | N7: Baru Berkembang: Belum Mencapai Ketuntasan, Remidial di Seluruh Bagian mulai teori membaca gambar teknik Layak: Belum Mencapai Ketuntasan, Remidial di Bagian yang Diperlukan Cakap: Sudah Mencapai Ketuntasan, Perlu dilatih berulang Kompeten : Sudah Mencapai Ketuntasan, Perlu diikutkan Uji Kompetensi LSP P1 sebagai operator mesin bubut
B9: NAMA SEKOLAH | C9: :
B10: BIDANG KEAHLIAN | C10: :
B12: PROGRAM KEAHLIAN | C12: :
B14: KONSENTRASI KEAHLIAN | C14: :
B17: NAMA MATA PELAJARAN | C17: :
B18: KELAS/ FASE | C18: :
B19: ALOKASI JAM PELAJARAN TOTAL | C19: :
B20: ALOKASI JP PROJEK (P5) | C20: :
B21: DURASI PEMBELAJARAN TIAP PERTEMUAN | C21: :
B24: NAMA ELEMEN CAPAIAN PEMBELAJARAN | C24: :
B25: URUTAN ELEMEN | C25: :
B26: MATERI/ KONTEN PEMBELAJARAN | C26: :
B31: KEMAMPUAN AKHIR FASE | C31: :
N41: Yogyakarta, Juli 2025
G42: Mengetahui :
G43: Kepala Sekolah | I43: WKS 1 | J43: Koord Mapel/KPK | N43: Pendidik,
G47: ='TP (9)'!C19 -> WIDADA, S.Pd., M.Pd. | I47: ='TP (9)'!E19 -> GUNAWAN, S.Pd., M.M. | J47: ='TP (9)'!G19 -> Drs. M. Hasannuddin | N47: ='TP (9)'!J19 -> Hermawan Rochmadi, S. Pd.
G48: ='TP (9)'!C20 -> NIP. 19690212 200012 1 002 | I48: ='TP (9)'!E20 -> NIP. 19711213 200501 1 004 | J48: ='TP (9)'!G20 -> NIP. 19670621 199412 1 003 | N48: ='TP (9)'!J20 -> NIP. 19920317 201903 1 009

Sheet KKM (8) batal
I1: F/751/WKS1/-/32
I2: 41783
A3: ANALISA PENGHITUNGAN KKTP
A4: SMK N 3 YOGYAKARTA
A5: TH 2023 - 2024
A6: NAMA SEKOLAH | B6: : SMK NEGERI 3 YOGYAKARTA
A7: MATA PELAJARAN | B7: :
A8: KELAS | B8: :
A9: FASE | B9: :
B11: :
A12: ALOKASI WAKTU
A13: Contoh:
A14: KOMPETENSI DASAR/ CAPAIAN PEMBELAJARAN | B14: INDIKATOR / MATERI POKOK | C14: INTAKE | D14: KOMPLEKSITAS | E14: DAYA DUKUNG | F14: SKM
F15: INDIKATOR | G15: KD/CP | H15: MATA PELAJARAN | I15: KET.
C16: 1 | D16: 2 | E16: 3 | F16: =SUM(C16:E18)/9*100 -> 66.666667 | G16: =(F16+F19)/2 -> 72.222222
C19: 2 | D19: 2 | E19: 3 | F19: =SUM(C19:E21)/9*100 -> 77.777778
A22: Koordinator Mapel | I22: Yogyakarta, Juli 2022
I23: Pendidik
C26: Mengetahui :
A27: Kepala Sekolah | I27: Waka Kurikulum
A31: Drs. B. Sabri | I31: Maryuli Darmawan, S.Pd. M.Eng
A32: NIP. 19630830 198703 1 003 | I32: NIP. 19700720 199802 1 003

Sheet MA- LKPD (11)
H1: F/751/WKS1/-/11
H2: 45483
A3: MODUL AJAR DAN LKPD
A5: LEMBAR TERSENDIRI

Sheet Dft Hdr (12)
L1: F/751/WKS1/-/12
L2: 45483
A3: DAFTAR HADIR
E4: Kelas | I4: : | J4: XII TM 3
A5: Konsentrasi Keahlian | C5: ='COVER '!E27 -> : Teknik Pemesinan | E5: Wali Kelas | I5: : Utomo Pujo Harjono, S.Pd
A6: Mata Pelajaran | C6: ='COVER '!E28 -> : Mata Pelajaran Pilihan (CAM) | E6: Semester | I6: ='COVER '!E31 -> : Gasal
A7: Kelas | C7: ='COVER '!E30 -> : XI TM3 | E7: Tahun Pelajaran | I7: ='COVER '!E32 -> : 2025/2026
A8: No | B8: NISN | C8: No Induk | D8: Nama | E8: JK | F8: Pertemuan ke/Tanggal
F9: 1 | G9: 2 | H9: 3 | I9: 4 | J9: 5 | K9: 6 | L9: 7 | M9: 8 | N9: 9 | O9: 10 | P9: 11 | Q9: 12
F10: 16/07/'25 | G10: 23/07/'25 | H10: 30/07/'25
A11: 1 | B11: 0077354629 | C11: TM.2321927 | D11: Advendra Maheswara | E11: L
A12: 2 | B12: 0087781251 | C12: TM.2321928 | D12: Christoper Galang Januart Pantera | E12: L
A13: 3 | B13: 0071233252 | C13: TM.2321929 | D13: Fran Oriza Arlandita Setiawan | E13: L
A14: 4 | B14: 0086935280 | C14: TM.2321930 | D14: Gerardus Rama Mahardika | E14: L
A15: 5 | B15: 0081827924 | C15: TM.2321931 | D15: Krisna Tri Agung Wicaksono | E15: L
A16: 6 | B16: 0083825158 | C16: TM.2321932 | D16: Laurenzo Maurin Zanakiray Jogo Ena | E16: L
A17: 7 | B17: 0074696776 | C17: TM.2321933 | D17: Mada Fikri Priandika Windastyan | E17: L
A18: 8 | B18: 0079361429 | C18: TM.2321935 | D18: Maulana Noval Ramadani | E18: L
A19: 9 | B19: 0071273234 | C19: TM.2321936 | D19: Mirza Arya Pratama | E19: L
A20: 10 | B20: 0081875805 | C20: TM.2321937 | D20: Misbahul Munir | E20: L
A21: 11 | B21: 0089954679 | C21: TM.2321938 | D21: Mochammad Fajarinto Winasis | E21: L
A22: 12 | B22: 0074116515 | C22: TM.2321939 | D22: Muhamad Adi Saputra | E22: L
... A44: 34 | B44: 0066305548 | C44: TM.2221238 | D44: Noverysa Yutha Desouza | E44: L
D45: L | E45: =COUNTIF(E11:E44,"L") -> 34
D46: P | E46: =COUNTIF(E11:E44,"P") -> 0
J47: Yogyakarta, …………………
J48: Pendidik,
J52: ='Prhtngn Mingg Ef(3)'!G87 -> Hermawan Rochmadi, S. Pd.
J53: ='Prhtngn Mingg Ef(3)'!G88 -> NIP. 19920317 201903 1 009

Sheet Penanganan Pesdik Brmslh (13)
F1: F/751/WKS1/-/13
F2: 45483
A3: PENANGANAN PESERTA DIDIK BERMASALAH
A5: Mata Pelajaran : | D5: Kelas/Semester : Gasal | F5: Tahun Pelajaran : 2024/2025
A7: NO | B7: NAMA PESERTA DIDIK | C7: MASALAH YANG DIHADAPI | D7: TANGGAL | E7: PENYELESAIAN MASALAH | F7: TANDA TANGAN SISWA
F31: Yogyakarta, Juli 2024
B32: Mengetahui :
B33: Kepala Sekolah | C33: WKS 1 | E33: Koord Mapel/KPK | F33: Pendidik,
B37: ='KKTP (10)'!G47 -> WIDADA, S.Pd., M.Pd. | C37: ='KKTP (10)'!I47 -> GUNAWAN, S.Pd., M.M. | E37: ='KKTP (10)'!J47 -> Drs. M. Hasannuddin | F37: ='KKTP (10)'!N47 -> Hermawan Rochmadi, S. Pd.
B38: ='KKTP (10)'!G48 -> NIP. 19690212 200012 1 002 | C38: ='KKTP (10)'!I48 -> NIP. 19711213 200501 1 004 | E38: ='KKTP (10)'!J48 -> NIP. 19670621 199412 1 003 | F38: ='KKTP (10)'!N48 -> NIP. 19920317 201903 1 009

Sheet FORMATIF (14)
AM1: F/751/WKS1/-/14
A2: LEMBAR PENILAIAN FORMATIF | AM2: 45117
A4: Mata Pelajaran : | F4: Kelas : | L4: Konsentrasi Keahlian : | X4: Semester : ……….. | AF4: Tahun Pelajaran : ……….
A6: NO | B6: Nama Siswa | C6: KURIKULUM MERDEKA
C7: ELEMEN | D7: 1 | G7: 2 | J7: 3 | M7: 4 | P7: 5 | S7: 6 | V7: 7 | Y7: 8 | AB7: 9 | AE7: PTS | AH7: PAS/PAT | AK7: RERATA | AN7: NA | AO7: PREDIKAT
C8: Tgl/bln
C9: NILAI | D9: NH | E9: R/P | F9: NA | G9: NH | H9: R/P | I9: NA | J9: NH | K9: R/P | L9: NA | M9: NH | N9: R/P | O9: NA | P9: NH | Q9: R/P | R9: NA | S9: NH | T9: R/P | U9: NA | V9: NH | W9: R/P | X9: NA | Y9: NH | Z9: R/P | AA9: NA | AB9: NH | AC9: R/P | AD9: NA | AE9: NH | AF9: R/P | AG9: NA | AH9: NH | AI9: R/P | AJ9: NA
A10: 1
A11: 2
A12: 3
A13: 4
A14: 5
A15: 6
A16: 7
A17: 8
A18: 9
A19: 10
A20: 11
A21: 12
... A41: 32
B43: Mengetahui | N43: Klasifikasi | AJ43: Yogyakarta, …………………………
B44: KP/Koord Mapel | E44: Ket : | N44: A | O44: ( 96 s/d 100 ) | S44: C+ | T44: ( 70 s/d 74 ) | Z44: NILAI RERATA | AJ44: Pendidik
E45: NH | G45: : | H45: Nilai Harian | N45: A- | O45: ( 91 s/d 95 ) | S45: C | T45: ( 65 s/d 69 ) | Y45: LPK.P = _____________ X 4
E46: R/P | G46: : | H46: Remidi/Pengayaan | N46: B+ | O46: ( 86 s/d 90 ) | S46: C- | T46: ( 60 s/d 64 ) | Z46: 100
B47: ='Prhtngn Mingg Ef(3)'!B87 -> Drs. M. Hasannuddin | E47: Penilaian dalam bentuk Angka Puluhan | N47: B | O47: ( 81 s/d 85 ) | S47: D+ | T47: ( 55 s/d 59 ) | AJ47: ='Prhtngn Mingg Ef(3)'!G87 -> Hermawan Rochmadi, S. Pd.
B48: ='Prhtngn Mingg Ef(3)'!B88 -> NIP. 19670621 199412 1 003 | N48: B- | O48: ( 75 s/d 80 ) | S48: D+ | T48: ( Kurang dari 54 ) | AJ48: ='Prhtngn Mingg Ef(3)'!G88 -> NIP. 19920317 201903 1 009

Sheet NILAI KETRAMPILAN (12.b)
AQ1: F/751/WKS1/37
A2: LEMBAR PENILAIAN KETRAMPILAN (K-4) | AQ2: 41783
A4: Mata Pelajaran : | F4: Kelas : | L4: Konsentrasi Keahlian : | W4: Semester : ………… | AA4: Tahun Pelajaran : …………… / ……………
A6: NO | B6: Nama Siswa | C6: KURIKULUM MERDEKA
C7: KD KE- | D7: 4.1 | G7: 4.2 | J7: 4.3 | M7: 4.4 | P7: 4.5 | S7: 4.6 | V7: 4.7 | Y7: 4.8 | AB7: 4.9 | AE7: 4.10 | AH7: 4.11 | AK7: 4.12 | AN7: RERATA | AQ7: Nilai Lap Pencap Komp. Ketrampiln (LPK.K) | AR7: PREDIKAT
C8: Tgl/bln
C9: NILAI | D9: NPr | E9: NPj | F9: Npo | G9: NPr | H9: NPj | I9: Npo | J9: NPr | K9: NPj | L9: Npo | M9: NPr | N9: NPj | O9: Npo | P9: NPr | Q9: NPj | R9: Npo | S9: NPr | T9: NPj | U9: Npo | V9: NPr | W9: NPj | X9: Npo | Y9: NPr | Z9: NPj | AA9: Npo | AB9: NPr | AC9: NPj | AD9: Npo | AE9: NPr | AF9: NPj | AG9: Npo | AH9: NPr | AI9: NPj | AJ9: Npo | AK9: NPr | AL9: NPj | AM9: Npo
A10: 1
A11: 2
A12: 3
A13: 4
A14: 5
A15: 6
A16: 7
A17: 8
A18: 9
A19: 10
A20: 11
A21: 12
... A41: 32
B43: Mengetahui | N43: Klasifikasi | AN43: Yogyakarta, ……………….
B44: KPK/Koord Mapel | E44: Ket : | N44: A | O44: ( 96 s/d 100 ) | S44: C+ | T44: ( 70 s/d 74 ) | AC44: NILAI RERATA | AN44: Pendidik
E45: Npr | G45: : | H45: Nilai Praktek | N45: A- | O45: ( 91 s/d 95 ) | S45: C | T45: ( 65 s/d 69 ) | AB45: LPK.K = _____________ X 4
E46: Npj | G46: : | H46: Nilai Projek | N46: B+ | O46: ( 86 s/d 90 ) | S46: C- | T46: ( 60 s/d 64 ) | AC46: 100
B47: ='Prhtngn Mingg Ef(3)'!B87 -> Drs. M. Hasannuddin | E47: Npo | G47: : | H47: Nilai Portopolio | N47: B | O47: ( 81 s/d 85 ) | S47: D+ | T47: ( 55 s/d 59 ) | AN47: ='Prhtngn Mingg Ef(3)'!G87 -> Hermawan Rochmadi, S. Pd.
B48: ='Prhtngn Mingg Ef(3)'!B88 -> NIP. 19670621 199412 1 003 | F48: Penilaian dalam Angka Puluhan | N48: B- | O48: ( 75 s/d 80 ) | S48: D+ | T48: ( Kurang dari 54 ) | AN48: ='Prhtngn Mingg Ef(3)'!G88 -> NIP. 19920317 201903 1 009
F50: Ket :
H51: 1 | I51: : | J51: Tidak Terampil
H52: 2 | I52: : | J52: Terampil Praktek Dengan Banyak bantuan Pembimbing
H53: 3 | I53: : | J53: Trampil Praktek Dengan Sedikit Bantuan pembimbing
H54: 4 | I54: : | J54: Trampil Praktek TaNKa Bantuan pembimbing

Sheet Sheet1

Sheet Analisis Kebutuhan Alat(15)
F1: F/751/WKS1/15
F2: 45117
A3: ANALISIS KEBUTUHAN ALAT
A6: NO | B6: KD | C6: NAMA ALAT/BAHAN | D6: SPESIFIKASI | E6: VOLUME | F6: KETERANGAN
F18: Yogyakarta,
B19: Mengetahui :
B20: KP/Koordinator Mapel | F20: Pendidik,
B24: ='Prhtngn Mingg Ef(3)'!B87 -> Drs. M. Hasannuddin | F24: ='Prhtngn Mingg Ef(3)'!G87 -> Hermawan Rochmadi, S. Pd.
B25: ='Prhtngn Mingg Ef(3)'!B88 -> NIP. 19670621 199412 1 003 | F25: ='Prhtngn Mingg Ef(3)'!G88 -> NIP. 19920317 201903 1 009
B27: Kepala SMK Negeri 3 Yogyakarta, | F27: Waka Kurikulum
B32: ='Prhtngn Mingg Ef(3)'!B95 -> WIDADA, S.Pd., M.Pd. | F32: ='Prhtngn Mingg Ef(3)'!G95 -> GUNAWAN, S.Pd., M.M.
B33: ='Prhtngn Mingg Ef(3)'!B96 -> NIP. 19690212 200012 1 002 | F33: ='Prhtngn Mingg Ef(3)'!G96 -> NIP. 19711213 200501 1 004

Sheet Buku Pegangan (16)
E1: F/751/WKS1/-/16
E2: 45117
A3: DAFTAR BUKU PEGANGAN
A5: Program Keahlian | C5: ='COVER '!E26 -> : Teknik Mesin
A6: Konsentrasi Keahlian | C6: ='COVER '!E27 -> : Teknik Pemesinan
A7: Mata Pelajaran | C7: ='COVER '!E28 -> : Mata Pelajaran Pilihan (CAM)
A8: Kelas | C8: ='COVER '!E30 -> : XI TM3
A9: Tahun Pelajaran | C9: ='COVER '!E32 -> : 2025/2026
A11: A | B11: PEGANGAN PENDIDIK
A13: No. | B13: Judul Buku | C13: Pengarang | D13: Penerbit | E13: Tahun
A27: B | B27: PEGANGAN PESERTA DIDIK
A29: No. | B29: Judul Buku | C29: Pengarang | D29: Penerbit | E29: Tahun
A31: 1
D36: Yogyakarta,
B37: Mengetahui :
B38: KP/Koordinator Mapel | D38: Pendidik,
B42: ='Prhtngn Mingg Ef(3)'!B37 -> Drs. M. Hasannuddin | D42: ='Prhtngn Mingg Ef(3)'!F37 -> Hermawan Rochmadi, S. Pd.
B43: ='Prhtngn Mingg Ef(3)'!B38 -> NIP. 19670621 199412 1 003 | D43: ='Prhtngn Mingg Ef(3)'!G88 -> NIP. 19920317 201903 1 009
B45: Kepala SMK Negeri 3 Yogyakarta, | D45: Waka Kurikulum
B49: ='Prhtngn Mingg Ef(3)'!B45 -> WIDADA, S.Pd., M.Pd. | D49: ='Prhtngn Mingg Ef(3)'!F45 -> GUNAWAN, S.Pd., M.M.
B50: ='Prhtngn Mingg Ef(3)'!B46 -> NIP. 19690212 200012 1 002 | D50: ='Prhtngn Mingg Ef(3)'!F46 -> NIP. 19711213 200501 1 004

Sheet Kisi-Kisi (17)
F1: F/751/WKS1/-/17
F2: 45117
A3: KISI-KISI PENYUSUNAN SOAL EVALUASI
A5: Mata Pelajaran : Sistem Kendali Elektronika | D5: Tahun Pelajaran : 2025 / 2026 | E5: Jumlah Soal : 35
A6: Kelas : XI TE 1 | D6: Bentuk Soal : a. Obyektif Tes | E6: Waktu : 90 Menit
A7: Konsentrasi Keahlian : Elektronika Industri
A9: NO | B9: KOMPETENSI DASAR | C9: JUMLAH SOAL | D9: URAIAN MATERI | E9: INDIKATOR | F9: NO SOAL | G9: KUNCI JAWABAN
A10: 1 | B10: Menjabarkan konsep sistem kendali elektronik | C10: 1 | D10: Mendeskripsikan konsep system kendali elektronik open loop dan close loop. | E10: Disajikan teks, peserta didik dapat mendeskripsikan konsep sistem kendali elektronik | F10: 1
A11: 2
A12: 3 | C12: 1 | D12: Mendeskripsikan fungsi - fungsi pada block diagram sistem kendali open loop dan close loop. | E12: Disajikan teks dan gambar, peserta didik dapat mendeskripsikan tugas dari masing – masing fungsi pada block diagram open loop dan close loop. | F12: 2
A13: 4
A14: 5
A15: 6 | C15: 1 | D15: Mendeskripsikan konsep system kendali elektronik open loop dan close loop. | E15: Disajikan teks, peserta didik dapat mendeskripsikan konsep sistem kendali elektronik | F15: 3
A16: 7
A17: 8 | C17: 1 | D17: Menerapkan penggunaan konsep sistem kendali elektronika open loop dan close loop pada kehidupan sehari – hari. | E17: Disajikan teks, peserta didik dapat menyimpulkan fungsi dan memberikan contoh penggunaan konsep sistem kendali elektronik open loop dan close loop. | F17: 4
A18: 9
A19: 10
A20: 11
A21: 12 | C21: 1 | D21: Mendeskripsikan control PID dalam sistem kendali elektronik. | E21: Disajikan teks, peserta didik dapat mendeskripsikan kontrol PID. | F21: 5
A22: 13
A23: 14 | C23: 1 | D23: Menerapkan penggunaan konsep sistem kendali elektronika open loop dan close loop pada kehidupan sehari – hari. | E23: Disajikan teks, peserta didik dapat menyimpulkan fungsi dan memberikan contoh penggunaan konsep sistem kendali elektronik open loop dan close loop. | F23: 6
A24: 15
A25: 16
A26: 17
A27: 18 | D27: Mendeskripsikan fungsi - fungsi pada block diagram sistem kendali open loop dan close loop. | E27: Disajikan teks dan gambar, peserta didik dapat mendeskripsikan tugas dari masing – masing fungsi pada block diagram open loop dan close loop. | F27: 7
A28: 19
A29: 20
A30: 21
A31: 22 | D31: Menyimpulkan keuntungan penggunaan sistem kendali elektronik dibanding sistem kendali mekanik (manual) | E31: Disajikan teks, peserta didik dapat menyimpulkan keuntungan penggunaan sistem kendali elektronik dibanding sistem kendali mekanik (manual) | F31: 8
A32: 23
A33: 24
A34: 25
A35: 26
A36: 27 | D36: Menjabarkan fungsi kaki Op-Amp LM741. | E36: Disajikan teks dan gambar, Op-Amp LM741, peserta didik mampu mengidentifikasi fungsi kaki Op-Amp LM741 | F36: 9 | L36: Mengetahui :
A37: 28 | L37: Kepala SMK Negeri 3 Yogyakarta, | Q37: Yogyakarta, ……………………………..
A38: 29 | Q38: Pendidik,
A39: 30
A40: 31 | D40: Menjabarkan fungsi kaki Op-Amp LM741. | E40: Disajikan teks dan gambar, Op-Amp LM741, peserta didik mampu mengidentifikasi fungsi kaki Op-Amp LM741 | F40: 10 | L40: Drs. Bujang Sabri
A41: 32 | L41: NIP. 19630830 198703 1 003 | Q41: ………………………………………………
A42: 33 | Q42: NIP. ………………………………………..
...

Sheet Anailis Hasil Ulangan (18)
H1: F/751/WKS1/-/18
H2: 45117
A4: ANBUSO TERLAMPIR
A5: Tidak Wajib semua mapel/ Non Mapel UN pakai Manual saja

Sheet Anl daya serap Hsl Ev (19)
AB1: F/84/WKS1/-/19
AB2: 45117
A3: ANALISIS KETUNTASAN DAN DAYA SERAP
A5: Mata Pelajaran | C5: ='COVER '!E28 -> : Mata Pelajaran Pilihan (CAM) | M5: Kelas/Semester | S5: : ………… | W5: KKTP | Z5: : …………….
A6: Bentuk Soal | C6: : …….. | M6: Jml Peserta Didik | S6: : ………… | W6: Tanggal Evaluasi | Z6: : …………….
A7: Jumlah Soal | C7: : …….. | M7: Elemen | S7: : …………
A9: NO | B9: NAMA | C9: NOMOR DAN BOBOT SOAL | S9: JML SKOR | T9: NILAI | U9: TERCAPAI (%) | V9: TUNTAS
W11: Keterangan :
A12: 1 | W12: 1 | X12: a. Nilai = Skor yg diperoleh X 100
A13: 2 | Y13: Total skor
A14: 3
A15: 4 | X15: b. Ketuntasan Klasikal = Jml Peserta Didik yg Tuntas x 100%
A16: 5 | Z16: Jml Peserta Didik
A17: 6 | W17: 2 | X17: Peserta didik disebut TUNTAS belajar jika telah menguasai bahan
A18: 7 | X18: (ketercapaian belajarnya) ≥ KKM
A19: 8 | W19: 3 | X19: Kelas disebut TUNTAS belajar jika Peserta Didik yang TUNTAS mencapai ≥ 85%
A20: 9
A21: 10
A22: 11 | W22: 4 | X22: a. Jumlah Peserta Didik | AB22: : ……
A23: 12 | X23: b. Jumlah Tuntas | AB23: : ……
A24: 13 | X24: c. Jumlah tidak tuntas | AB24: : ……
A25: 14 | X25: d. Ketuntasan Klasikal | Z25: : …... %
A26: 15 | X26: e. Secara Klasikal | Z26: : Tuntas / Tidak Tuntas
A27: 16 | W27: 5 | X27: Daya Serap =
A28: 17 | Y28: Isi rumus mencari Daya Serap dan ketentuannya
A29: 18
A30: 19
A31: 20
A32: 21 | W32: Kesimpulan :
A33: 22 | W33: 1 | X33: Perlu perbaikan secara klasikal untuk soal
A34: 23 | X34: nomor : ……………………………………………………..
A35: 24 | W35: 2 | X35: Perlu program perbaikan secara individual
A36: 25 | X36: untuk Peserta Didik nomor
A37: 26 | X37: …………………………………..
A38: 27 | W38: 3 | X38: Perlu program pengayaan untuk
A39: 28 | X39: Peserta Didik nomor
A40: 29
A41: 32
B43: Mengetahui : | T43: Yogyakarta, ………………
B44: Kepala Sekolah | T44: Pendidik,
...

Sheet Prg. Perb.&pengyn(20)
H1: F/751/WKS1/-/20
H2: 45117
A3: PROGRAM PERBAIKAN / PENGAYAAN
A4: Tahapan :
A5: 1. Analisis Ketuntasan Belajar
A6: 2. Melakukan Pembinaan/Pengarahan sesuai dengan jenis kesukaran
A7: 3. Pemberian Tugas / Materi Perbaikan / Pengayaan
A8: 4. Pemberian Nilai Perbaikan / Pengayaan
A10: 1. Perhitungan Ketuntasan Belajar
A11: Mata Pelajaran | C11: ='COVER '!E28 -> : Mata Pelajaran Pilihan (CAM)
A12: Kelas/Program | C12: ='COVER '!E30 -> : XI TM3
A13: Kompetensi Dasar | C13: : ……………
A14: Tanggal Tes | C14: : ……………
B16: NILAI (INTERVAL) | D16: JUMLAH SISWA | F16: KETERANGAN
B17: N < 75 | F17: Mengikuti Perbaikan
B18: N > 75 | F18: Mengikuti Pengayaan
A21: 2. Sebelum mendapat tugas, peserta didik mendapat arahan/bimbingan berupa jenis kesukaran
A23: NO | B23: NAMA | D23: NILAI | E23: KESUKARAN | H23: KETERANGAN
A24: 1
A25: 2
A26: 3
A27: 4
A28: 5
A29: 6
A30: 7
A31: 8
A32: 9
A33: 10
A34: 11
A35: 12
... A37: 14
A38: 3. Setelah mendapat bimbingan siswa mendapat tugas
A39: a. Remedial / PR soal nomor ……………………………….*)
A40: b. Membuat ringkasan / ikhtisar materi tentang ………………
A41: c. Mengerjakan soal berikutnya
A42: d. …………………………….
A43: *) Sebut jenis dan bukti fisiknya dilampirkan
A44: 4. Data peserta didik yang mendapat nilai Perbaikan / Pengayaan
A46: NO | B46: NAMA | D46: NILAI | H46: KETERANGAN
D47: Sebelum Perbaikan | E47: Setelah Perbaikam
...

Sheet Prog. Pengayaan(21)
H1: F/751/WKS1/-/21
H2: 45117
A3: PROGRAM PENGAYAAN
A4: Tahapan :
A5: 1. Analisis Ketuntasan Belajar
A6: 2. Melakukan Pembinaan/Pengarahan sesuai dengan jenis kesukaran
A7: 3. Pemberian Tugas / Materi Perbaikan / Pengayaan
A8: 4. Pemberian Nilai Perbaikan / Pengayaan
A10: 1. Perhitungan Ketuntasan Belajar
A11: Mata Pelajaran | C11: ='COVER '!E28 -> : Mata Pelajaran Pilihan (CAM)
A12: Kelas/Program | C12: ='COVER '!E30 -> : XI TM3
A13: Kompetensi Dasar | C13: : ……………
A14: Tanggal Tes | C14: : ……………
B16: NILAI (INTERVAL) | D16: JUMLAH SISWA | F16: KETERANGAN
B17: N < 75 | F17: Mengikuti Perbaikan
B18: N > 75 | F18: Mengikuti Pengayaan
A20: 2. Sebelum mendapat tugas pengayaan, peserta didik mendapat arahan/bimbingan.
A22: NO | B22: NAMA | D22: NILAI | E22: JENIS ARAHAN/BIMBINGAN | H22: KETERANGAN
A23: 1
A24: 2
A25: 3
A26: 4
A27: 5
A28: 6
A29: 7
A30: 8
A31: 9
A32: 10
A33: 11
A34: 12
... A36: 14
A37: 3. Setelah mendapat bimbingan siswa mendapat tugas
A38: a. Membuat ringkasan / ikhtisar materi tentang ………………………………………...……….*)
A39: b. Mengerjakan soal berikutnya
A40: c. …………………………….
A41: *) Sebut jenis dan bukti fisiknya dilampirkan
A42: 4. Data peserta didik yang mendapat nilai Pengayaan
A44: NO | B44: NAMA | D44: NILAI | H44: KETERANGAN
D45: Sebelum Perbaikan | E45: Setelah Perbaikam
E46: Tgl. ……. | F46: Tgl. ……. | G46: Tgl. …….
...

Sheet Agenda  (22)
F1: F/751/WKS1/-/22
A2: AGENDA HARIAN | F2: 45117
A4: Nama | C4: : | D4: ='COVER '!F34 -> Hermawan Rochmadi, S. Pd. | E4: Kelas : | F4: ='COVER '!E30 -> : XI TM3
A5: NIP. | C5: : | D5: ='COVER '!F35 -> 19920317 201903 1 009 | E5: Tahun Pelajaran : | F5: ='COVER '!E32 -> : 2025/2026
A6: Mata Pelajaran | C6: : | D6: ='COVER '!E28 -> : Mata Pelajaran Pilihan (CAM)
A8: Hari/Tgl | B8: Kelas | C8: Jam | D8: Materi yang disampaikan (Elemen) | E8: No.RPP/MA | F8: Keterangan
A56: Hari/Tgl | B56: Kelas | C56: Jam | D56: Materi yang disampaikan (SK/KD) | E56: No.RPP/MA | F56: Keterangan
E97: Yogyakarta,
A99: Koordinator Mapel/KPK | E99: Pendidik,
A103: ='Prhtngn Mingg Ef(3)'!B87 -> Drs. M. Hasannuddin | E103: ='COVER '!F34 -> Hermawan Rochmadi, S. Pd.
A104: ='Prhtngn Mingg Ef(3)'!B88 -> NIP. 19670621 199412 1 003 | E104: ='Prhtngn Mingg Ef(3)'!G88 -> NIP. 19920317 201903 1 009
D107: Mengetahui :
A108: Kepala Sekolah | E108: WKS 1
A112: ='Prhtngn Mingg Ef(3)'!B95 -> WIDADA, S.Pd., M.Pd. | E112: ='Prhtngn Mingg Ef(3)'!G95 -> GUNAWAN, S.Pd., M.M.
A113: ='Prhtngn Mingg Ef(3)'!B96 -> NIP. 19690212 200012 1 002 | E113: ='Prhtngn Mingg Ef(3)'!G96 -> NIP. 19711213 200501 1 004

Sheet Target&Capaian Kur ( (23)
M1: F/84/WKS1/-/23
M2: 45117
B3: TARGET DAN PENCAPAIAN TARGET KURIKULUM
B5: Program Keahlian | E5: ='COVER '!E26 -> : Teknik Mesin
B6: Konsentrasi Keahlian | E6: ='COVER '!E27 -> : Teknik Pemesinan
B7: Mata Pelajaran | E7: ='COVER '!E28 -> : Mata Pelajaran Pilihan (CAM)
B8: Fase | E8: ='COVER '!E29 -> : F
B9: Kelas | E9: ='COVER '!E30 -> : XI TM3
B10: Semester | E10: ='COVER '!E31 -> : Gasal
B11: Tahun Pelajaran | E11: ='COVER '!E32 -> : 2025/2026
C12: 100 | G12: Contoh
C13: 95
C14: 90
C15: 85
C16: 80
C17: 75
C18: 70
C19: 65
C20: 60
C21: 55
C22: 50
C23: 45
C24: 40
... C30: 10
C31: 5 | D31: 0.06
C32: 0
D33: Jul | E33: Ags | F33: Sept | G33: Okt | H33: Nov | I33: Des | J33: Jan | K33: Feb | L33: Mar | M33: Apr | N33: Mei | O33: Jun
B34: Keterangan :
B35: Target Kurikulum =
B36: Jumlah jam pelajaran yang harus diselesaikan | K36: x | L36: 1 | N36: (tampilan berupa histogram)
B37: Jumlah jam pelajaran yang harus diselesaikan dalam satu tahun
B39: Pencapaian Target Kurikulum :
B40: Jumlah jam pelajaran yang sudah diselesaikan | K40: x | L40: 1 | N40: (tampilan berupa diagram garis)
B41: Jumlah jam pelajaran yang harus diselesaikan dalam satu tahun
B42: Catatan :
K44: Yogyakarta, Juli 2025
B45: Mengetahui :
B46: KPK/Koordinator Mapel | K46: Pendidik,
B49: ='Prhtngn Mingg Ef(3)'!B87 -> Drs. M. Hasannuddin | K49: ='Prhtngn Mingg Ef(3)'!G87 -> Hermawan Rochmadi, S. Pd.
B50: ='Prhtngn Mingg Ef(3)'!B88 -> NIP. 19670621 199412 1 003 | K50: ='Prhtngn Mingg Ef(3)'!G88 -> NIP. 19920317 201903 1 009
...

Sheet AJP (22)
E1: F/751/WKS1/-/47
E2: 41783
A3: ANALISIS JAM PEMBELAJARAN
A5: Program Keahlian | C5: ='COVER '!E26 -> : Teknik Mesin
A6: Konsentrasi Keahlian | C6: ='COVER '!E27 -> : Teknik Pemesinan
A7: Mata Pelajaran | C7: ='COVER '!E28 -> : Mata Pelajaran Pilihan (CAM)
A8: Fase | C8: ='COVER '!E29 -> : F
A9: Kelas | C9: ='COVER '!E30 -> : XI TM3
A10: Semester | C10: ='COVER '!E31 -> : Gasal
A11: Tahun Pelajaran | C11: ='COVER '!E32 -> : 2025/2026
A12: No. | B12: Standar Kompetensi/Kompetensi Dasar | C12: Kode Profil | D12: Jumlah Jam | E12: Tempat Pembelajaran
E13: Sekolah (Jam.pel) | F13: DU/DI (Jam.pel)
A14: 1 | B14: Teknik Pemesinan Bubut/Membubut Ulir | C14: TPMBK.1 | D14: 20 | E14: 20 | F14: 0
B15: JUMLAH | D15: =SUM(D14:D14) -> 20 | E15: =SUM(E14:E14) -> 20 | F15: =F14 -> 0
C17: Yogyakarta, Juli 2025
B18: Mengetahui :
B19: KP/Koordinator Mapel | C19: Pendidik,
B24: NIP. | C24: NIP.
B26: Kepala Sekolah | C26: WKS 1
B30: Drs. B Sabri | C30: Maryuli Darmawan, S.Pd. M.Eng
B31: NIP. 19630830 198703 1 003 | C31: NIP. 19700720 199802 1 003

Sheet Analisis SKM (8)
M1: F/751/WKS1/-/32
M2: 43636
A3: ANALISIS SKM SESUAI DENGAN SILABUS KURIKULUM 2013
A4: MATA PELAJARAN................
A5: NO | B5: KOMP. DASAR | C5: IPK | D5: SKM IPK | H5: SKM MATERI POKOK | L5: SKM KOMP. DASAR | M5: SKM MAPEL | N5: KET
D6: Kompl | E6: Daya Duk | F6: Input | G6: SKM | H6: Kompl | I6: Daya Duk | J6: Input | K6: SKM
A7: 1 | B7: 3.1 dan 4.1 | C7: 1
C8: 2
C9: 3
A11: 2 | B11: 3.2 dan 4.2 | C11: 1
C12: 2
C13: 3
A15: 3 | B15: 3.3 dan 4.3 | C15: 1
C16: 2
C17: 1
C18: 2
B19: dst
L22: Yogyakarta, Juli 2019
B23: Mengetahui :
B24: KP/Koordinator Mapel | L24: Pendidik,
B29: NIP. | L29: NIP.
B31: Kepala Sekolah | L31: WKS 1
B35: Drs. B Sabri | L35: Maryuli Darmawan, S.Pd. M.Eng
B36: NIP. 19630830 198703 1 003 | L36: NIP. 19700720 199802 1 003

Sheet Rencana Penilaian (24)
K1: F/751/WKS1/-/24
K2: 45117
A4: PERENCANAAN PENILAIAN
A5: SMK NEGERI 3 YOGYAKARTA TAHUN PELAJARAN 2025 - 2026
A6: Program Keahlian | D6: ='COVER '!E26 -> : Teknik Mesin
A7: Konsentrasi Keahlian | D7: ='COVER '!E27 -> : Teknik Pemesinan
A8: Mata Pelajaran | D8: ='COVER '!E28 -> : Mata Pelajaran Pilihan (CAM)
A9: Fase | D9: ='COVER '!E29 -> : F
A10: Kelas | D10: ='COVER '!E30 -> : XI TM3
A11: Semester | D11: ='COVER '!E31 -> : Gasal
A12: Tahun Pelajaran | D12: ='COVER '!E32 -> : 2025/2026
A14: NO | B14: ELEMEN | C14: P1 | D14: P2 | E14: P3 | F14: P4 | G14: P5 | H14: P6 | I14: P7 | J14: P8 | K14: P9 | L14: P10 (UTS)
C15: LISAN | D15: TULIS | E15: TUGAS | F15: PORT FL | G15: PG/ESAY | H15: KINERJA PRODUK | I15: KINERJA PRAKTIK | J15: PROYEK | K15: PORT.FL | L15: PG/ESAY
A16: 1
A18: 2
A20: 3
A22: 4 | O22: Keterangan :
A24: 5
A26: 6
A28: 7
A30: DST
A33: Keterangan :
A34: Penilaian Pengetahuan : | F34: Penilaian Ketrampilan :
A35: P1 : Penilaian Lisan | F35: P6 : Penilaian Kinerja (produk)
A36: P2 : Penilaian Tertulis | F36: P6 : Penilaian Kinerja (praktik)
A37: P3 : Penilaian Penugasan | F37: P8 : Penilaian Proyek
A38: P4 : Penilaian Portofolio | F38: P9 : Penilaian Portofolio
A39: P5 : Penilaian Harian
I41: Yogyakarta, Juli 2025
B42: Mengetahui :
B43: KPK/Koordinator Mapel | I43: Pendidik,
B47: ='Prhtngn Mingg Ef(3)'!B87 -> Drs. M. Hasannuddin | I47: ='Prhtngn Mingg Ef(3)'!G87 -> Hermawan Rochmadi, S. Pd.
B48: ='Prhtngn Mingg Ef(3)'!B88 -> NIP. 19670621 199412 1 003 | I48: ='Prhtngn Mingg Ef(3)'!G88 -> NIP. 19920317 201903 1 009
B50: Kepala Sekolah | I50: WKS 1
B54: ='Prhtngn Mingg Ef(3)'!B95 -> WIDADA, S.Pd., M.Pd. | I54: ='Prhtngn Mingg Ef(3)'!G95 -> GUNAWAN, S.Pd., M.M.
B55: ='Prhtngn Mingg Ef(3)'!B96 -> NIP. 19690212 200012 1 002 | I55: ='Prhtngn Mingg Ef(3)'!G96 -> NIP. 19711213 200501 1 004

Sheet Rekap Nil.Peng.(24)
Y1: F/751/WKS1/-/49
Y2: 43636
A3: REKAPITULASI PENILAIAN PENGETAHUAN
A4: Program Keahlian | C4: :
A5: Mata Pelajaran | C5: :
A6: Kelas | C6: :
A7: Semester | C7: :
A8: No | B8: Nama | D8: P1 | G8: P2 | J8: P3 | M8: P4 | P8: P5 ( UH) | S8: P10 (UTS) PG, Essay | V8: P11 | AA8: N KD
C9: KD | D9: Lisan | G9: Tulis | J9: Tugas | M9: Portfol | P9: PG, Essay | V9: UAS | Y9: ΣNA | Z9: ΣB | AB9: NR
D10: N | E10: B | F10: NA | G10: N | H10: B | I10: NA | J10: N | K10: B | L10: NA | M10: N | N10: B | O10: NA | P10: N | Q10: B | R10: NA | S10: N | T10: B | U10: NA | V10: N | W10: B | X10: NA
A11: 1 | B11: Aliansyah | C11: 0.12569444 | D11: 90 | E11: 2 | F11: 180 | G11: 80 | H11: 1 | I11: 80 | M11: 80 | N11: 3 | O11: 240 | Y11: 500 | Z11: 6 | AA11: 83 | AB11: 74
C12: 0.12638889 | D12: 70 | E12: 2 | F12: 140 | M12: 80 | N12: 3 | O12: 240 | Y12: 380 | Z12: 5 | AA12: 76
C13: 0.12708333 | G13: 70 | H13: 1 | I13: 70 | J13: 80 | K13: 2 | L13: 160 | M13: 80 | N13: 3 | O13: 240 | Y13: 470 | Z13: 6 | AA13: 78
C14: 0.12777778 | P14: 85 | Q14: 1 | R14: 85 | S14: 60 | T14: 2 | U14: 120 | V14: 60 | W14: 3 | X14: 180 | Y14: 385 | Z14: 6 | AA14: 64
C15: 0.12847222 | S15: 70 | T15: 2 | U15: 140 | V15: 70 | W15: 3 | X15: 210 | Y15: 350 | Z15: 5 | AA15: 70
A16: 2 | B16: Aminuddin | C16: 0.12569444 | D16: 80 | E16: 2 | F16: 160 | G16: 86 | H16: 1 | I16: 86 | M16: 80 | N16: 3 | O16: 240 | Y16: 486 | Z16: 6 | AA16: 81 | AB16: 80
C17: 0.12638889 | D17: 80 | E17: 2 | F17: 160 | M17: 80 | N17: 3 | O17: 240 | Y17: 400 | Z17: 5 | AA17: 80
C18: 0.12708333 | G18: 85 | H18: 1 | I18: 85 | J18: 80 | K18: 2 | L18: 160 | M18: 80 | N18: 3 | O18: 240 | Y18: 485 | Z18: 6 | AA18: 81
C19: 0.12777778 | P19: 85 | Q19: 1 | R19: 85 | S19: 85 | T19: 2 | U19: 170 | V19: 80 | W19: 3 | X19: 240 | Y19: 495 | Z19: 6 | AA19: 83
C20: 0.12847222 | S20: 70 | T20: 2 | U20: 140 | V20: 80 | W20: 3 | X20: 240 | Y20: 380 | Z20: 5 | AA20: 76
A21: 3 | B21: Budi Sulistyo | C21: 0.12569444 | D21: 90 | E21: 2 | F21: 180 | G21: 80 | H21: 1 | I21: 80 | M21: 80 | N21: 3 | O21: 240 | Y21: 500 | Z21: 6 | AA21: 83 | AB21: 82
C22: 0.12638889 | D22: 90 | E22: 2 | F22: 180 | M22: 80 | N22: 3 | O22: 240 | Y22: 420 | Z22: 5 | AA22: 84
C23: 0.12708333 | G23: 80 | H23: 1 | I23: 80 | J23: 75 | K23: 2 | L23: 150 | M23: 80 | N23: 3 | O23: 240 | Y23: 470 | Z23: 6 | AA23: 78
C24: 0.12777778 | P24: 85 | Q24: 1 | R24: 85 | S24: 80 | T24: 2 | U24: 160 | V24: 85 | W24: 3 | X24: 255 | Y24: 500 | Z24: 6 | AA24: 83
C25: 0.12847222 | S25: 80 | T25: 2 | U25: 160 | V25: 80 | W25: 3 | X25: 240 | Y25: 400 | Z25: 5 | AA25: 80
A26: dst
A28: Keterangan :
A29: N : Nilai | C29: NA : Jumlah N x A
A30: B : Bobot | C30: B : jumlah Bobot
A31: NA : N x B | C31: NKD : Jumlah N x A / Jumlah Bobot
C32: NR : Nilai Raport
S37: Yogyakarta, Juli 2019
A38: Mengetahui :
A39: KP/Koordinator Mapel | S39: Pendidik,
A44: NIP. | S44: NIP.
A46: Kepala Sekolah | S46: WKS 1
A50: Drs. B Sabri | S50: Maryuli Darmawan, S.Pd. M.Eng
A51: NIP. 19630830 198703 1 003 | S51: NIP. 19700720 199802 1 003

Sheet Rekap Nil. Ket (25)
Y1: F/751/WKS1/-/50
Y2: 43636
A3: REKAPITULASI PENILAIAN KETERAMPILAN
A4: Program Keahlian | C4: :
A5: Mata Pelajaran | C5: :
A6: Kelas | C6: :
A7: Semester | C7: :
A8: No | B8: Nama | C8: KD | D8: P6 | G8: P7 | J8: Nilai | M8: P8 | P8: Nilai | S8: P9 | V8: Nilai | AA8: N KD
D9: Kinerja (Produk) | G9: Kinerja (Praktik) | J9: Kinerja | M9: Proyek | P9: Proyek | S9: Portofolio | V9: Portofolio | Y9: ΣNA | Z9: ΣB | AB9: NR
D10: N | E10: B | F10: NA | G10: N | H10: B | I10: NA | J10: NO | K10: B | L10: NA | M10: N | N10: B | O10: NA | P10: NO | Q10: B | R10: NA | S10: N | T10: B | U10: NA | V10: NO | W10: B | X10: NA
A11: 1 | B11: Aliansyah | C11: 0.12569444 | D11: 80 | E11: 1 | F11: 80 | Y11: 80 | Z11: 1 | AA11: 80 | AB11: 82
C12: 0.12638889 | G12: 80 | H12: 1 | I12: 80 | Y12: 80 | Z12: 1 | AA12: 80
C13: 0.12708333 | J13: 80 | K13: 1 | L13: 80 | Y13: 80 | Z13: 1 | AA13: 80
C14: 0.12777778 | M14: 80 | N14: 2 | O14: 160 | P14: 80 | Q14: 2 | R14: 160 | Y14: 80 | Z14: 2 | AA14: 160
C15: 0.12847222 | S15: 90 | T15: 1 | U15: 90 | V15: 90 | W15: 1 | X15: 90 | Y15: 90 | Z15: 1 | AA15: 90
A16: 2 | B16: Aminuddin | C16: 0.12569444 | D16: 80 | E16: 1 | F16: 80 | Y16: 80 | Z16: 1 | AA16: 80 | AB16: 78
C17: 0.12638889 | G17: 80 | H17: 1 | I17: 80 | Y17: 80 | Z17: 1 | AA17: 80
C18: 0.12708333 | J18: 80 | K18: 1 | L18: 80 | Y18: 80 | Z18: 1 | AA18: 80
C19: 0.12777778 | M19: 80 | N19: 2 | O19: 160 | P19: 75 | Q19: 2 | R19: 150 | Y19: 75 | Z19: 2 | AA19: 150
C20: 0.12847222 | S20: 80 | T20: 1 | U20: 80 | V20: 80 | W20: 1 | X20: 80 | Y20: 80 | Z20: 1 | AA20: 80
A21: 3 | B21: Budi Sulistyo | C21: 0.12569444 | D21: 85 | E21: 1 | F21: 85 | Y21: 85 | Z21: 1 | AA21: 85 | AB21: 84
C22: 0.12638889 | G22: 80 | H22: 1 | I22: 80 | Y22: 80 | Z22: 1 | AA22: 80
C23: 0.12708333 | J23: 90 | K23: 1 | L23: 90 | Y23: 90 | Z23: 1 | AA23: 90
C24: 0.12777778 | M24: 80 | N24: 2 | O24: 160 | P24: 80 | Q24: 2 | R24: 160 | Y24: 80 | Z24: 2 | AA24: 160
C25: 0.12847222 | S25: 90 | T25: 1 | U25: 90 | V25: 90 | W25: 1 | X25: 90 | Y25: 90 | Z25: 1 | AA25: 90
A27: Keterangan :
A28: N : Nilai | C28: NA : Jumlah N x A
A29: B : Bobot | C29: B : jumlah Bobot
A30: NA : N x B | C30: NKD : Jumlah N x A / Jumlah Bobot
C31: NR : Nilai Raport
S36: Yogyakarta, Juli 2019
A37: Mengetahui :
A38: KP/Koordinator Mapel | S38: Pendidik,
A43: NIP. | S43: NIP.
A45: Kepala Sekolah | S45: WKS 1
A49: Drs. B Sabri | S49: Maryuli Darmawan, S.Pd. M.Eng
A50: NIP. 19630830 198703 1 003 | S50: NIP. 19700720 199802 1 003
B54: SEKOLAH MENENTUKAN KRITERIA PENILAIAN SIKAP
B55: NORMA AGAMA | C55: PACARAN
B56: NORMA SUSILA | C56: AGAMA

Sheet Telaah Soal PG (25)
G1: F/751/WKS1/-/25
G2: 45117
A4: INSTRUMEN TELAAH SOAL PILIHAN GANDA
A5: Sekolah | C5: : SMKN 3 Yogyakarta
A6: Konsentrasi Keahlian | C6: ='COVER '!E27 -> : Teknik Pemesinan
A7: Mata Pelajaran | C7: ='COVER '!E28 -> : Mata Pelajaran Pilihan (CAM)
A8: Kelas | C8: ='COVER '!E30 -> : XI TM3
A9: Semester | C9: ='COVER '!E31 -> : Gasal
A10: Elemen | C10: :
A11: NO | B11: ASPEK YANG DINILAI | C11: RESPON | D11: SKOR SOAL NO
A12: I | B12: MATERI | D12: 1 | E12: 2 | F12: 3 | G12: 4 | H12: 5 | I12: 6 | J12: dst
B13: 1. Soal sesuai indicator | C13: (1) soal sesuai indikator
C14: (0) soal tidak sesuai indicator
B15: 2. Soal dan pilihan jawaban tidak bersifat SARA, propaganda, pornografi, bermuatan politis, dan kekerasan | C15: (1) Soal dan pilihan jawaban tidak bersifat SARA, propaganda, pornografi, bermuatan politis, dan kekerasan
C16: (0) Soal dan pilihan jawaban bersifat SARA, propaganda, pornografi, bermuatan politis, dan kekerasan
B17: 3. Pilihan jawaban homogen dan logis | C17: (2) pilihan jawaban homogin dan logis
C18: (1)pilihan jawaban homogin atau logis
C19: (0) pilihan jawaban tidak homogin dan tidak logis
B20: 4. Hanya ada satu kunci jawaban | C20: (1) kunci jawaban hanya satu
C21: (0) kunci jawaban lebih dari satu atau tidak ada atau salah
A22: II | B22: KOMPETENSI
B23: 1. Pokok soal jelas dan tegas | C23: (2) Pokok soal jelas dan tegas
C24: (1) Pokok soal jelas atau tegas
C25: (0) Pokok soal tidak jelas dan tidak tegas
B26: 2. Pokok soal atau pilihan jawaban merupakan pernyataan yang diperlukan | C26: (1) Pokok soal atau pilihan jawaban merupakan pernyataan yang diperlukan
C27: (0) Pokok soal atau pilihan jawaban bukan merupakan pernyataan yang diperlukan
B28: 3. Pokok soal tidak member petunjuk ke arah jawaban yang benar | C28: (1) Pokok soal tidak member petunjuk ke arah jawaban yang benar
C29: (0) Pokok soal tidak member petunjuk ke arah jawaban yang benar
B30: 4. Pokok soal tidak mengandung pernyataan yang bersifat negatif ganda | C30: (1) Tidak mengandung pernyataan yang bersifat negatif ganda
C31: (0) Mengandung pernyataan yang bersifat negatif ganda
B32: 5. Panjang rumusan pilihan jawaban relative sama | C32: (1) Panjang rumusan pilihan jawaban relative sama
C33: (0) Salah satu rumusan pilihan jawaban panjang
B34: 6. Pilihan jawaban tidak mengandung pernyataan “semua pilihan jawaban di atas salah” atau “ semua pilihan jawaban di atas benar” | C34: (1) Pilihan jawaban tidak mengandung pernyataan “semua pilihan jawaban di atas salah” atau “ semua pilihan jawaban di atas benar”
C35: (0) Pilihan jawaban mengandung pernyataan “semua pilihan jawaban di atas salah” atau “ semua pilihan jawaban di atas benar”
B37: 7. Pilihan jawaban yang berbentuk angka atau waktu disusun berdasarkan urutan besar kecilnya nilai angka tersebut, atau kronologis | C37: (*) pilihan jawaban tidak berbentuk urutan angka atau urutan waktu
C38: (1) Pilihan jawaban yang berbentuk angka disusun berdasarkan urutan kecil ke besar atau sebaliknya dan pilihan jawaban waktu berdasarkan kronologisnya
C39: (0) Pilihan yang berbentuk angka tidak disusun berdasarkan urutan kecil ke besar atau sebaliknya dan pilihan jawaban waktu tidak berdasarkan kronologisnya
B40: 8. Gambar, grafik, table, diagram, dan sejenisnya yang terdapat pada soal jelas dan berfungsi | C40: (*) tidk terdapat gambar, grafik, table, diagram, dan sejenisnya
C41: (1) gambar, grafik, table, diagram, dan sejenisnya pada soal jelas dan berfungsi
C42: (0) gambar, grafik, table, diagram, dan sejenisnya pada soal jelas dan berfungsi
...

Sheet Telaah Soal Essay (26)
G1: F/751/WKS1/-/26
G2: 45117
A3: INSTRUMEN TELAAH SOAL URAIAN/ESSAY
A4: Sekolah | C4: ='Telaah Soal PG (25)'!C5 -> : SMKN 3 Yogyakarta
A5: Konsentrasi Keahlian | C5: ='COVER '!E27 -> : Teknik Pemesinan
A6: Mata Pelajaran | C6: ='COVER '!E28 -> : Mata Pelajaran Pilihan (CAM)
A7: Kelas | C7: ='COVER '!E30 -> : XI TM3
A8: Semester | C8: ='COVER '!E31 -> : Gasal
A9: Elemen | C9: ='Telaah Soal PG (25)'!C10 -> :
A10: NO | B10: ASPEK YANG DINILAI | C10: RESPON | D10: SKOR SOAL NO
A11: I | B11: MATERI | D11: 1 | E11: 2 | F11: 3 | G11: 4 | H11: 5 | I11: 6 | J11: dst
B12: 1. Soal sesuai dengan indikator (menuntut tes bentuk uraian) | C12: (1) soal sesuai indikator
C13: (0) soal tidak sesuai indicator
B14: 2. Batasan pertanyaan dan jawaban yang diharapkan sesuai | C14: (1) Soal dan pilihan jawaban tidak bersifat SARA, propaganda, pornografi, bermuatan politis, dan kekerasan
C15: (0) Soal dan pilihan jawaban bersifat SARA, propaganda, pornografi, bermuatan politis, dan kekerasan
B16: A. Materi yang diukur sesuai dengan kompetensi (UKRK) | C16: (2) pilihan jawaban homogin dan logis
C17: (1)pilihan jawaban homogin atau logis
C18: (0) pilihan jawaban tidak homogin dan tidak logis
B19: B. Isi materi yang ditanyakan sesuai dengan jenjang, jenis sekolah, dan tingkat kelas | C19: (1) kunci jawaban hanya satu
C20: (0) kunci jawaban lebih dari satu atau tidak ada atau salah
A21: II | B21: KOMPETENSI
B22: 1. Ada petunjuk yang jelas mengenai cara mengerjakan soal | C22: (1) Ada petunjuk yang jelas mengenai cara mengerjakan soal
C23: (0) Tidak ada petunjuk yang jelas mengenai cara mengerjakan soal
B24: 2. Rumusan kalimat Soal/ pertanyaan menggunakan kata tanya atau perintah yang menuntut jawaban terurai | C24: (1) Rumusan kalimat Soal/ pertanyaan menggunakan kata tanya atau perintah yang menuntut jawaban terurai
C25: (0) Rumusan kalimat Soal/ pertanyaan tidak menggunakan kata tanya atau perintah yang menuntut jawaban terurai
B26: 3. Gambar/grafik/tabel/diagram dan sejenisnya harus jelas dan berfungsi | C26: (1) Gambar/grafik/tabel/diagram dan sejenisnya harus jelas dan berfungsi
C27: (0) Gambar/grafik/tabel/diagram dan sejenisnya tidak jelas dan tidakberfungsi
B28: 4. Ada pedoman penskoran | C28: (1) Ada pedoman penskoran
C29: (0) Tidak ada pedoman penskoran
A30: III | B30: BAHASA
B31: 1. Rumusan kalimat soal/pertanyaan komunikatif | C31: (1) Rumusan kalimat soal/pertanyaan komunikatif
C32: (0) Rumusan kalimat soal/pertanyaan tidak komunikatif
B33: 2. Butir soal menggunakan bahasa Indonesia yang baku | C33: (*) khusus Mulok Bahasa Daerah/sejenisnya pilih opsi ini
C34: (1) Butir soal menggunakan bahasa Indonesia yang baku
C35: (0) Butir soal tidak menggunakan bahasa Indonesia yang baku
B36: 3. Tidak mengandung kata-kata/kalimat yang menimbulkan penafsiran ganda atau salah pengertian | C36: (1) Tidak mengandung kata-kata/kalimat yang menimbulkan penafsiran ganda atau salah pengertian
C37: (0) mengandung kata-kata/kalimat yang menimbulkan penafsiran ganda atau salah pengertian
